Workbook

Sheet 202604工资表
A1: 2026年04月份薪资表
A2: 序号 | B2: 姓名 | C2: 公司 | D2: 起薪时间 | E2: 花名册薪资 | F2: EG差额 | G2: 月薪基数 | H2: GI差额2 | I2: 月薪资总额 | J2: 岗位 | K2: 基本薪资 | L2: 绩效薪资基数 | M2: 绩效等级 | N2: 绩效薪资 | O2: 应发薪资 | P2: 补发扣 | Q2: 实际应发薪资 | R2: 月薪资总额和应发差异 | S2: 列1 | T2: 列2
A3: =ROW(A3)-2 -> 1 | B3: 一 | C3: 尚诚能源 | D3: 44713 | E3: 10000 | F3: =E3-G3 -> 0 | G3: 10000 | H3: =G3-I3 -> 0 | I3: =G3 -> 10000 | J3: 南京大学 | K3: {=ROUND(_xlfn.IFS(OR(J3="南京大学",J3="BOSS",J3="实习生",J3="人力劳务"),I3,J3="部门负责人",I3*0.6,J3="员工",I3*0.7),2)} -> 10000 | L3: {=ROUND(_xlfn.IFS(OR(J3="南京大学",J3="BOSS",J3="实习生",J3="人力劳务"),I3*0,J3="部门负责人",I3*0.4,J3="员工",I3*0.3),2)} -> 0 | M3: 无等级 | N3: {=ROUND(_xlfn.IFS(M3="A",L3*1.5,M3="B",L3*1.2,M3="C",L3*1,M3="D",L3*0.8,M3="E",L3*0.6,M3="无等级",L3*0),2)} -> 0 | O3: =ROUND(K3+N3,2) -> 10000 | P3: 0 | Q3: =ROUND(O3+P3,2) -> 10000 | R3: =O3-I3 -> 0
A4: =ROW(A4)-2 -> 2 | B4: 二 | C4: 尚诚能源 | D4: 44805 | E4: 10000 | F4: =E4-G4 -> 0 | G4: 10000 | H4: =G4-I4 -> 0 | I4: =G4 -> 10000 | J4: 南京大学 | K4: {=ROUND(_xlfn.IFS(OR(J4="南京大学",J4="BOSS",J4="实习生",J4="人力劳务"),I4,J4="部门负责人",I4*0.6,J4="员工",I4*0.7),2)} -> 10000 | L4: {=ROUND(_xlfn.IFS(OR(J4="南京大学",J4="BOSS",J4="实习生",J4="人力劳务"),I4*0,J4="部门负责人",I4*0.4,J4="员工",I4*0.3),2)} -> 0 | M4: 无等级 | N4: {=ROUND(_xlfn.IFS(M4="A",L4*1.5,M4="B",L4*1.2,M4="C",L4*1,M4="D",L4*0.8,M4="E",L4*0.6,M4="无等级",L4*0),2)} -> 0 | O4: =ROUND(K4+N4,2) -> 10000 | P4: 0 | Q4: =ROUND(O4+P4,2) -> 10000 | R4: =O4-I4 -> 0
A5: =ROW(A5)-2 -> 3 | B5: 三 | C5: 尚诚能源 | D5: 44958 | E5: 10000 | F5: =E5-G5 -> 0 | G5: 10000 | H5: =G5-I5 -> 0 | I5: =G5 -> 10000 | J5: 南京大学 | K5: {=ROUND(_xlfn.IFS(OR(J5="南京大学",J5="BOSS",J5="实习生",J5="人力劳务"),I5,J5="部门负责人",I5*0.6,J5="员工",I5*0.7),2)} -> 10000 | L5: {=ROUND(_xlfn.IFS(OR(J5="南京大学",J5="BOSS",J5="实习生",J5="人力劳务"),I5*0,J5="部门负责人",I5*0.4,J5="员工",I5*0.3),2)} -> 0 | M5: 无等级 | N5: {=ROUND(_xlfn.IFS(M5="A",L5*1.5,M5="B",L5*1.2,M5="C",L5*1,M5="D",L5*0.8,M5="E",L5*0.6,M5="无等级",L5*0),2)} -> 0 | O5: =ROUND(K5+N5,2) -> 10000 | P5: 0 | Q5: =ROUND(O5+P5,2) -> 10000 | R5: =O5-I5 -> 0
A6: =ROW(A6)-2 -> 4 | B6: 四 | C6: 尚诚能源 | D6: 44986 | E6: 10000 | F6: =E6-G6 -> 0 | G6: 10000 | H6: =G6-I6 -> 0 | I6: =G6 -> 10000 | J6: 南京大学 | K6: {=ROUND(_xlfn.IFS(OR(J6="南京大学",J6="BOSS",J6="实习生",J6="人力劳务"),I6,J6="部门负责人",I6*0.6,J6="员工",I6*0.7),2)} -> 10000 | L6: {=ROUND(_xlfn.IFS(OR(J6="南京大学",J6="BOSS",J6="实习生",J6="人力劳务"),I6*0,J6="部门负责人",I6*0.4,J6="员工",I6*0.3),2)} -> 0 | M6: 无等级 | N6: {=ROUND(_xlfn.IFS(M6="A",L6*1.5,M6="B",L6*1.2,M6="C",L6*1,M6="D",L6*0.8,M6="E",L6*0.6,M6="无等级",L6*0),2)} -> 0 | O6: =ROUND(K6+N6,2) -> 10000 | P6: 0 | Q6: =ROUND(O6+P6,2) -> 10000 | R6: =O6-I6 -> 0
A7: =ROW(A7)-2 -> 5 | B7: 五 | C7: 尚诚能源 | D7: 45231 | E7: 10000 | F7: =E7-G7 -> 0 | G7: 10000 | H7: =G7-I7 -> 0 | I7: =G7 -> 10000 | J7: 南京大学 | K7: {=ROUND(_xlfn.IFS(OR(J7="南京大学",J7="BOSS",J7="实习生",J7="人力劳务"),I7,J7="部门负责人",I7*0.6,J7="员工",I7*0.7),2)} -> 10000 | L7: {=ROUND(_xlfn.IFS(OR(J7="南京大学",J7="BOSS",J7="实习生",J7="人力劳务"),I7*0,J7="部门负责人",I7*0.4,J7="员工",I7*0.3),2)} -> 0 | M7: 无等级 | N7: {=ROUND(_xlfn.IFS(M7="A",L7*1.5,M7="B",L7*1.2,M7="C",L7*1,M7="D",L7*0.8,M7="E",L7*0.6,M7="无等级",L7*0),2)} -> 0 | O7: =ROUND(K7+N7,2) -> 10000 | P7: 0 | Q7: =ROUND(O7+P7,2) -> 10000 | R7: =O7-I7 -> 0
A8: =ROW(A8)-2 -> 6 | B8: 六 | C8: 尚诚能源 | D8: 45658 | E8: 10000 | F8: =E8-G8 -> 0 | G8: 10000 | H8: =G8-I8 -> 0 | I8: =G8 -> 10000 | J8: 南京大学 | K8: {=ROUND(_xlfn.IFS(OR(J8="南京大学",J8="BOSS",J8="实习生",J8="人力劳务"),I8,J8="部门负责人",I8*0.6,J8="员工",I8*0.7),2)} -> 10000 | L8: {=ROUND(_xlfn.IFS(OR(J8="南京大学",J8="BOSS",J8="实习生",J8="人力劳务"),I8*0,J8="部门负责人",I8*0.4,J8="员工",I8*0.3),2)} -> 0 | M8: 无等级 | N8: {=ROUND(_xlfn.IFS(M8="A",L8*1.5,M8="B",L8*1.2,M8="C",L8*1,M8="D",L8*0.8,M8="E",L8*0.6,M8="无等级",L8*0),2)} -> 0 | O8: =ROUND(K8+N8,2) -> 10000 | P8: 0 | Q8: =ROUND(O8+P8,2) -> 10000 | R8: =O8-I8 -> 0
A9: =ROW(A9)-2 -> 7 | B9: 七 | C9: 尚诚能源 | D9: 45658 | E9: 10000 | F9: =E9-G9 -> 0 | G9: 10000 | H9: =G9-I9 -> 0 | I9: =G9 -> 10000 | J9: 南京大学 | K9: {=ROUND(_xlfn.IFS(OR(J9="南京大学",J9="BOSS",J9="实习生",J9="人力劳务"),I9,J9="部门负责人",I9*0.6,J9="员工",I9*0.7),2)} -> 10000 | L9: {=ROUND(_xlfn.IFS(OR(J9="南京大学",J9="BOSS",J9="实习生",J9="人力劳务"),I9*0,J9="部门负责人",I9*0.4,J9="员工",I9*0.3),2)} -> 0 | M9: 无等级 | N9: {=ROUND(_xlfn.IFS(M9="A",L9*1.5,M9="B",L9*1.2,M9="C",L9*1,M9="D",L9*0.8,M9="E",L9*0.6,M9="无等级",L9*0),2)} -> 0 | O9: =ROUND(K9+N9,2) -> 10000 | P9: 0 | Q9: =ROUND(O9+P9,2) -> 10000 | R9: =O9-I9 -> 0
A10: =ROW(A10)-2 -> 8 | B10: 八 | C10: 尚诚能源 | D10: 45809 | E10: 10000 | F10: =E10-G10 -> 0 | G10: 10000 | H10: =G10-I10 -> 0 | I10: =G10 -> 10000 | J10: 南京大学 | K10: {=ROUND(_xlfn.IFS(OR(J10="南京大学",J10="BOSS",J10="实习生",J10="人力劳务"),I10,J10="部门负责人",I10*0.6,J10="员工",I10*0.7),2)} -> 10000 | L10: {=ROUND(_xlfn.IFS(OR(J10="南京大学",J10="BOSS",J10="实习生",J10="人力劳务"),I10*0,J10="部门负责人",I10*0.4,J10="员工",I10*0.3),2)} -> 0 | M10: 无等级 | N10: {=ROUND(_xlfn.IFS(M10="A",L10*1.5,M10="B",L10*1.2,M10="C",L10*1,M10="D",L10*0.8,M10="E",L10*0.6,M10="无等级",L10*0),2)} -> 0 | O10: =ROUND(K10+N10,2) -> 10000 | P10: 0 | Q10: =ROUND(O10+P10,2) -> 10000 | R10: =O10-I10 -> 0
A11: =ROW(A11)-2 -> 9 | B11: 九 | C11: 尚诚能源 | D11: 45809 | E11: 10000 | F11: =E11-G11 -> 0 | G11: 10000 | H11: =G11-I11 -> 0 | I11: =G11 -> 10000 | J11: 南京大学 | K11: {=ROUND(_xlfn.IFS(OR(J11="南京大学",J11="BOSS",J11="实习生",J11="人力劳务"),I11,J11="部门负责人",I11*0.6,J11="员工",I11*0.7),2)} -> 10000 | L11: {=ROUND(_xlfn.IFS(OR(J11="南京大学",J11="BOSS",J11="实习生",J11="人力劳务"),I11*0,J11="部门负责人",I11*0.4,J11="员工",I11*0.3),2)} -> 0 | M11: 无等级 | N11: {=ROUND(_xlfn.IFS(M11="A",L11*1.5,M11="B",L11*1.2,M11="C",L11*1,M11="D",L11*0.8,M11="E",L11*0.6,M11="无等级",L11*0),2)} -> 0 | O11: =ROUND(K11+N11,2) -> 10000 | P11: 0 | Q11: =ROUND(O11+P11,2) -> 10000 | R11: =O11-I11 -> 0
A12: =ROW(A12)-2 -> 10 | B12: 一十 | C12: 尚诚能源 | D12: 45870 | E12: 10000 | F12: =E12-G12 -> 0 | G12: 10000 | H12: =G12-I12 -> 0 | I12: =G12 -> 10000 | J12: 南京大学 | K12: {=ROUND(_xlfn.IFS(OR(J12="南京大学",J12="BOSS",J12="实习生",J12="人力劳务"),I12,J12="部门负责人",I12*0.6,J12="员工",I12*0.7),2)} -> 10000 | L12: {=ROUND(_xlfn.IFS(OR(J12="南京大学",J12="BOSS",J12="实习生",J12="人力劳务"),I12*0,J12="部门负责人",I12*0.4,J12="员工",I12*0.3),2)} -> 0 | M12: 无等级 | N12: {=ROUND(_xlfn.IFS(M12="A",L12*1.5,M12="B",L12*1.2,M12="C",L12*1,M12="D",L12*0.8,M12="E",L12*0.6,M12="无等级",L12*0),2)} -> 0 | O12: =ROUND(K12+N12,2) -> 10000 | P12: 0 | Q12: =ROUND(O12+P12,2) -> 10000 | R12: =O12-I12 -> 0
A13: =ROW(A13)-2 -> 11 | B13: 一十一 | C13: 尚诚能源 | D13: 45901 | E13: 10000 | F13: =E13-G13 -> 0 | G13: 10000 | H13: =G13-I13 -> 0 | I13: =G13 -> 10000 | J13: 南京大学 | K13: {=ROUND(_xlfn.IFS(OR(J13="南京大学",J13="BOSS",J13="实习生",J13="人力劳务"),I13,J13="部门负责人",I13*0.6,J13="员工",I13*0.7),2)} -> 10000 | L13: {=ROUND(_xlfn.IFS(OR(J13="南京大学",J13="BOSS",J13="实习生",J13="人力劳务"),I13*0,J13="部门负责人",I13*0.4,J13="员工",I13*0.3),2)} -> 0 | M13: 无等级 | N13: {=ROUND(_xlfn.IFS(M13="A",L13*1.5,M13="B",L13*1.2,M13="C",L13*1,M13="D",L13*0.8,M13="E",L13*0.6,M13="无等级",L13*0),2)} -> 0 | O13: =ROUND(K13+N13,2) -> 10000 | P13: 0 | Q13: =ROUND(O13+P13,2) -> 10000 | R13: =O13-I13 -> 0
A14: =ROW(A14)-2 -> 12 | B14: 一十二 | C14: 尚诚能源 | D14: 46023 | E14: 10000 | F14: =E14-G14 -> 0 | G14: 10000 | H14: =G14-I14 -> 0 | I14: =G14 -> 10000 | J14: 南京大学 | K14: {=ROUND(_xlfn.IFS(OR(J14="南京大学",J14="BOSS",J14="实习生",J14="人力劳务"),I14,J14="部门负责人",I14*0.6,J14="员工",I14*0.7),2)} -> 10000 | L14: {=ROUND(_xlfn.IFS(OR(J14="南京大学",J14="BOSS",J14="实习生",J14="人力劳务"),I14*0,J14="部门负责人",I14*0.4,J14="员工",I14*0.3),2)} -> 0 | M14: 无等级 | N14: {=ROUND(_xlfn.IFS(M14="A",L14*1.5,M14="B",L14*1.2,M14="C",L14*1,M14="D",L14*0.8,M14="E",L14*0.6,M14="无等级",L14*0),2)} -> 0 | O14: =ROUND(K14+N14,2) -> 10000 | P14: 0 | Q14: =ROUND(O14+P14,2) -> 10000 | R14: =O14-I14 -> 0
A15: =ROW(A15)-2 -> 13 | B15: 一十三 | C15: 尚诚能源 | D15: 46054 | E15: 10000 | F15: =E15-G15 -> 0 | G15: 10000 | H15: =G15-I15 -> 0 | I15: =G15 -> 10000 | J15: 南京大学 | K15: {=ROUND(_xlfn.IFS(OR(J15="南京大学",J15="BOSS",J15="实习生",J15="人力劳务"),I15,J15="部门负责人",I15*0.6,J15="员工",I15*0.7),2)} -> 10000 | L15: {=ROUND(_xlfn.IFS(OR(J15="南京大学",J15="BOSS",J15="实习生",J15="人力劳务"),I15*0,J15="部门负责人",I15*0.4,J15="员工",I15*0.3),2)} -> 0 | M15: 无等级 | N15: {=ROUND(_xlfn.IFS(M15="A",L15*1.5,M15="B",L15*1.2,M15="C",L15*1,M15="D",L15*0.8,M15="E",L15*0.6,M15="无等级",L15*0),2)} -> 0 | O15: =ROUND(K15+N15,2) -> 10000 | P15: 0 | Q15: =ROUND(O15+P15,2) -> 10000 | R15: =O15-I15 -> 0
A16: =ROW(A16)-15 -> 1 | B16: 一 | C16: 南大尚诚 | D16: 44713 | E16: 10000 | F16: =E16-G16 -> 0 | G16: 10000 | H16: =G16-I16 -> 0 | I16: =IF(G16="120元/天",_xlfn.XLOOKUP(B16,'202604考勤'!B:B,'202604考勤'!AI:AI,"无")*120,IF(S16="转正",ROUND(G16/DAY(EOMONTH(T16,0))*(DAY(EOMONTH(T16,0))-DAY(T16)+1)+(G16*0.8)/DAY(EOMONTH(T16,0))*(DAY(T16)-1),2),IF(OR(AND(S16="入职",DAY(T16)=1),AND(S16="离职",T16=EOMONTH(T16,0))),G16,IF(OR(S16="离职",S16="入职"),ROUND(G16/21.75*_xlfn.XLOOKUP(B16,'202604考勤'!B:B,'202604考勤'!AI:AI,0),2),G16)))) -> 10000 | J16: BOSS | K16: {=ROUND(_xlfn.IFS(OR(J16="南京大学",J16="BOSS",J16="实习生",J16="人力劳务"),I16,J16="部门负责人",I16*0.6,J16="员工",I16*0.7),2)} -> 10000 | L16: {=ROUND(_xlfn.IFS(OR(J16="南京大学",J16="BOSS",J16="实习生",J16="人力劳务"),I16*0,J16="部门负责人",I16*0.4,J16="员工",I16*0.3),2)} -> 0 | M16: 无等级 | N16: {=ROUND(_xlfn.IFS(M16="A",L16*1.5,M16="B",L16*1.2,M16="C",L16*1,M16="D",L16*0.8,M16="E",L16*0.6,M16="无等级",L16*0),2)} -> 0 | O16: =ROUND(K16+N16,2) -> 10000 | P16: 0 | Q16: =ROUND(O16+P16,2) -> 10000 | R16: =O16-I16 -> 0
A17: =ROW(A17)-15 -> 2 | B17: 二 | C17: 尚诚能源 | D17: 45512 | E17: 10000 | F17: =E17-G17 -> 0 | G17: 10000 | H17: =G17-I17 -> 0 | I17: =IF(G17="120元/天",_xlfn.XLOOKUP(B17,'202604考勤'!B:B,'202604考勤'!AI:AI,"无")*120,IF(S17="转正",ROUND(G17/DAY(EOMONTH(T17,0))*(DAY(EOMONTH(T17,0))-DAY(T17)+1)+(G17*0.8)/DAY(EOMONTH(T17,0))*(DAY(T17)-1),2),IF(OR(AND(S17="入职",DAY(T17)=1),AND(S17="离职",T17=EOMONTH(T17,0))),G17,IF(OR(S17="离职",S17="入职"),ROUND(G17/21.75*_xlfn.XLOOKUP(B17,'202604考勤'!B:B,'202604考勤'!AI:AI,0),2),G17)))) -> 10000 | J17: BOSS | K17: {=ROUND(_xlfn.IFS(OR(J17="南京大学",J17="BOSS",J17="实习生",J17="人力劳务"),I17,J17="部门负责人",I17*0.6,J17="员工",I17*0.7),2)} -> 10000 | L17: {=ROUND(_xlfn.IFS(OR(J17="南京大学",J17="BOSS",J17="实习生",J17="人力劳务"),I17*0,J17="部门负责人",I17*0.4,J17="员工",I17*0.3),2)} -> 0 | M17: 无等级 | N17: {=ROUND(_xlfn.IFS(M17="A",L17*1.5,M17="B",L17*1.2,M17="C",L17*1,M17="D",L17*0.8,M17="E",L17*0.6,M17="无等级",L17*0),2)} -> 0 | O17: =ROUND(K17+N17,2) -> 10000 | P17: 0 | Q17: =ROUND(O17+P17,2) -> 10000 | R17: =O17-I17 -> 0
A18: =ROW(A18)-15 -> 3 | B18: 三 | C18: 尚诚能源 | D18: 44713 | E18: 10000 | F18: =E18-G18 -> 0 | G18: 10000 | H18: =G18-I18 -> 0 | I18: =IF(G18="120元/天",_xlfn.XLOOKUP(B18,'202604考勤'!B:B,'202604考勤'!AI:AI,"无")*120,IF(S18="转正",ROUND(G18/DAY(EOMONTH(T18,0))*(DAY(EOMONTH(T18,0))-DAY(T18)+1)+(G18*0.8)/DAY(EOMONTH(T18,0))*(DAY(T18)-1),2),IF(OR(AND(S18="入职",DAY(T18)=1),AND(S18="离职",T18=EOMONTH(T18,0))),G18,IF(OR(S18="离职",S18="入职"),ROUND(G18/21.75*_xlfn.XLOOKUP(B18,'202604考勤'!B:B,'202604考勤'!AI:AI,0),2),G18)))) -> 10000 | J18: 员工 | K18: {=ROUND(_xlfn.IFS(OR(J18="南京大学",J18="BOSS",J18="实习生",J18="人力劳务"),I18,J18="部门负责人",I18*0.6,J18="员工",I18*0.7),2)} -> 7000 | L18: {=ROUND(_xlfn.IFS(OR(J18="南京大学",J18="BOSS",J18="实习生",J18="人力劳务"),I18*0,J18="部门负责人",I18*0.4,J18="员工",I18*0.3),2)} -> 3000 | M18: C | N18: {=ROUND(_xlfn.IFS(M18="A",L18*1.5,M18="B",L18*1.2,M18="C",L18*1,M18="D",L18*0.8,M18="E",L18*0.6,M18="无等级",L18*0),2)} -> 3000 | O18: =ROUND(K18+N18,2) -> 10000 | P18: 0 | Q18: =ROUND(O18+P18,2) -> 10000 | R18: =O18-I18 -> 0
A19: =ROW(A19)-15 -> 4 | B19: 四 | C19: 南大尚诚 | D19: 44713 | E19: 10000 | F19: =E19-G19 -> 0 | G19: 10000 | H19: =G19-I19 -> 0 | I19: =IF(G19="120元/天",_xlfn.XLOOKUP(B19,'202604考勤'!B:B,'202604考勤'!AI:AI,"无")*120,IF(S19="转正",ROUND(G19/DAY(EOMONTH(T19,0))*(DAY(EOMONTH(T19,0))-DAY(T19)+1)+(G19*0.8)/DAY(EOMONTH(T19,0))*(DAY(T19)-1),2),IF(OR(AND(S19="入职",DAY(T19)=1),AND(S19="离职",T19=EOMONTH(T19,0))),G19,IF(OR(S19="离职",S19="入职"),ROUND(G19/21.75*_xlfn.XLOOKUP(B19,'202604考勤'!B:B,'202604考勤'!AI:AI,0),2),G19)))) -> 10000 | J19: 部门负责人 | K19: {=ROUND(_xlfn.IFS(OR(J19="南京大学",J19="BOSS",J19="实习生",J19="人力劳务"),I19,J19="部门负责人",I19*0.6,J19="员工",I19*0.7),2)} -> 6000 | L19: {=ROUND(_xlfn.IFS(OR(J19="南京大学",J19="BOSS",J19="实习生",J19="人力劳务"),I19*0,J19="部门负责人",I19*0.4,J19="员工",I19*0.3),2)} -> 4000 | M19: C | N19: {=ROUND(_xlfn.IFS(M19="A",L19*1.5,M19="B",L19*1.2,M19="C",L19*1,M19="D",L19*0.8,M19="E",L19*0.6,M19="无等级",L19*0),2)} -> 4000 | O19: =ROUND(K19+N19,2) -> 10000 | P19: 0 | Q19: =ROUND(O19+P19,2) -> 10000 | R19: =O19-I19 -> 0
A20: =ROW(A20)-15 -> 5 | B20: 五 | C20: 南大尚诚 | D20: 44713 | E20: 10000 | F20: =E20-G20 -> 0 | G20: 10000 | H20: =G20-I20 -> 0 | I20: =IF(G20="120元/天",_xlfn.XLOOKUP(B20,'202604考勤'!B:B,'202604考勤'!AI:AI,"无")*120,IF(S20="转正",ROUND(G20/DAY(EOMONTH(T20,0))*(DAY(EOMONTH(T20,0))-DAY(T20)+1)+(G20*0.8)/DAY(EOMONTH(T20,0))*(DAY(T20)-1),2),IF(OR(AND(S20="入职",DAY(T20)=1),AND(S20="离职",T20=EOMONTH(T20,0))),G20,IF(OR(S20="离职",S20="入职"),ROUND(G20/21.75*_xlfn.XLOOKUP(B20,'202604考勤'!B:B,'202604考勤'!AI:AI,0),2),G20)))) -> 10000 | J20: 员工 | K20: {=ROUND(_xlfn.IFS(OR(J20="南京大学",J20="BOSS",J20="实习生",J20="人力劳务"),I20,J20="部门负责人",I20*0.6,J20="员工",I20*0.7),2)} -> 7000 | L20: {=ROUND(_xlfn.IFS(OR(J20="南京大学",J20="BOSS",J20="实习生",J20="人力劳务"),I20*0,J20="部门负责人",I20*0.4,J20="员工",I20*0.3),2)} -> 3000 | M20: C | N20: {=ROUND(_xlfn.IFS(M20="A",L20*1.5,M20="B",L20*1.2,M20="C",L20*1,M20="D",L20*0.8,M20="E",L20*0.6,M20="无等级",L20*0),2)} -> 3000 | O20: =ROUND(K20+N20,2) -> 10000 | P20: 0 | Q20: =ROUND(O20+P20,2) -> 10000 | R20: =O20-I20 -> 0
A21: =ROW(A21)-15 -> 6 | B21: 六 | C21: 南大尚诚 | D21: 44713 | E21: 10000 | F21: =E21-G21 -> 0 | G21: 10000 | H21: =G21-I21 -> 0 | I21: =IF(G21="120元/天",_xlfn.XLOOKUP(B21,'202604考勤'!B:B,'202604考勤'!AI:AI,"无")*120,IF(S21="转正",ROUND(G21/DAY(EOMONTH(T21,0))*(DAY(EOMONTH(T21,0))-DAY(T21)+1)+(G21*0.8)/DAY(EOMONTH(T21,0))*(DAY(T21)-1),2),IF(OR(AND(S21="入职",DAY(T21)=1),AND(S21="离职",T21=EOMONTH(T21,0))),G21,IF(OR(S21="离职",S21="入职"),ROUND(G21/21.75*_xlfn.XLOOKUP(B21,'202604考勤'!B:B,'202604考勤'!AI:AI,0),2),G21)))) -> 10000 | J21: 员工 | K21: {=ROUND(_xlfn.IFS(OR(J21="南京大学",J21="BOSS",J21="实习生",J21="人力劳务"),I21,J21="部门负责人",I21*0.6,J21="员工",I21*0.7),2)} -> 7000 | L21: {=ROUND(_xlfn.IFS(OR(J21="南京大学",J21="BOSS",J21="实习生",J21="人力劳务"),I21*0,J21="部门负责人",I21*0.4,J21="员工",I21*0.3),2)} -> 3000 | M21: C | N21: {=ROUND(_xlfn.IFS(M21="A",L21*1.5,M21="B",L21*1.2,M21="C",L21*1,M21="D",L21*0.8,M21="E",L21*0.6,M21="无等级",L21*0),2)} -> 3000 | O21: =ROUND(K21+N21,2) -> 10000 | P21: 0 | Q21: =ROUND(O21+P21,2) -> 10000 | R21: =O21-I21 -> 0
A22: =ROW(A22)-15 -> 7 | B22: 七 | C22: 南大尚诚 | D22: 44713 | E22: 10000 | F22: =E22-G22 -> 0 | G22: 10000 | H22: =G22-I22 -> 0 | I22: =IF(G22="120元/天",_xlfn.XLOOKUP(B22,'202604考勤'!B:B,'202604考勤'!AI:AI,"无")*120,IF(S22="转正",ROUND(G22/DAY(EOMONTH(T22,0))*(DAY(EOMONTH(T22,0))-DAY(T22)+1)+(G22*0.8)/DAY(EOMONTH(T22,0))*(DAY(T22)-1),2),IF(OR(AND(S22="入职",DAY(T22)=1),AND(S22="离职",T22=EOMONTH(T22,0))),G22,IF(OR(S22="离职",S22="入职"),ROUND(G22/21.75*_xlfn.XLOOKUP(B22,'202604考勤'!B:B,'202604考勤'!AI:AI,0),2),G22)))) -> 10000 | J22: 员工 | K22: {=ROUND(_xlfn.IFS(OR(J22="南京大学",J22="BOSS",J22="实习生",J22="人力劳务"),I22,J22="部门负责人",I22*0.6,J22="员工",I22*0.7),2)} -> 7000 | L22: {=ROUND(_xlfn.IFS(OR(J22="南京大学",J22="BOSS",J22="实习生",J22="人力劳务"),I22*0,J22="部门负责人",I22*0.4,J22="员工",I22*0.3),2)} -> 3000 | M22: C | N22: {=ROUND(_xlfn.IFS(M22="A",L22*1.5,M22="B",L22*1.2,M22="C",L22*1,M22="D",L22*0.8,M22="E",L22*0.6,M22="无等级",L22*0),2)} -> 3000 | O22: =ROUND(K22+N22,2) -> 10000 | P22: 0 | Q22: =ROUND(O22+P22,2) -> 10000 | R22: =O22-I22 -> 0
A23: =ROW(A23)-15 -> 8 | B23: 八 | C23: 南大尚诚 | D23: 44713 | E23: 10000 | F23: =E23-G23 -> 0 | G23: 10000 | H23: =G23-I23 -> 0 | I23: =IF(G23="120元/天",_xlfn.XLOOKUP(B23,'202604考勤'!B:B,'202604考勤'!AI:AI,"无")*120,IF(S23="转正",ROUND(G23/DAY(EOMONTH(T23,0))*(DAY(EOMONTH(T23,0))-DAY(T23)+1)+(G23*0.8)/DAY(EOMONTH(T23,0))*(DAY(T23)-1),2),IF(OR(AND(S23="入职",DAY(T23)=1),AND(S23="离职",T23=EOMONTH(T23,0))),G23,IF(OR(S23="离职",S23="入职"),ROUND(G23/21.75*_xlfn.XLOOKUP(B23,'202604考勤'!B:B,'202604考勤'!AI:AI,0),2),G23)))) -> 10000 | J23: 员工 | K23: {=ROUND(_xlfn.IFS(OR(J23="南京大学",J23="BOSS",J23="实习生",J23="人力劳务"),I23,J23="部门负责人",I23*0.6,J23="员工",I23*0.7),2)} -> 7000 | L23: {=ROUND(_xlfn.IFS(OR(J23="南京大学",J23="BOSS",J23="实习生",J23="人力劳务"),I23*0,J23="部门负责人",I23*0.4,J23="员工",I23*0.3),2)} -> 3000 | M23: C | N23: {=ROUND(_xlfn.IFS(M23="A",L23*1.5,M23="B",L23*1.2,M23="C",L23*1,M23="D",L23*0.8,M23="E",L23*0.6,M23="无等级",L23*0),2)} -> 3000 | O23: =ROUND(K23+N23,2) -> 10000 | P23: 0 | Q23: =ROUND(O23+P23,2) -> 10000 | R23: =O23-I23 -> 0
A24: =ROW(A24)-15 -> 9 | B24: 九 | C24: 南大尚诚 | D24: 44713 | E24: 10000 | F24: =E24-G24 -> 0 | G24: 10000 | H24: =G24-I24 -> 0 | I24: =IF(G24="120元/天",_xlfn.XLOOKUP(B24,'202604考勤'!B:B,'202604考勤'!AI:AI,"无")*120,IF(S24="转正",ROUND(G24/DAY(EOMONTH(T24,0))*(DAY(EOMONTH(T24,0))-DAY(T24)+1)+(G24*0.8)/DAY(EOMONTH(T24,0))*(DAY(T24)-1),2),IF(OR(AND(S24="入职",DAY(T24)=1),AND(S24="离职",T24=EOMONTH(T24,0))),G24,IF(OR(S24="离职",S24="入职"),ROUND(G24/21.75*_xlfn.XLOOKUP(B24,'202604考勤'!B:B,'202604考勤'!AI:AI,0),2),G24)))) -> 10000 | J24: 部门负责人 | K24: {=ROUND(_xlfn.IFS(OR(J24="南京大学",J24="BOSS",J24="实习生",J24="人力劳务"),I24,J24="部门负责人",I24*0.6,J24="员工",I24*0.7),2)} -> 6000 | L24: {=ROUND(_xlfn.IFS(OR(J24="南京大学",J24="BOSS",J24="实习生",J24="人力劳务"),I24*0,J24="部门负责人",I24*0.4,J24="员工",I24*0.3),2)} -> 4000 | M24: C | N24: {=ROUND(_xlfn.IFS(M24="A",L24*1.5,M24="B",L24*1.2,M24="C",L24*1,M24="D",L24*0.8,M24="E",L24*0.6,M24="无等级",L24*0),2)} -> 4000 | O24: =ROUND(K24+N24,2) -> 10000 | P24: 0 | Q24: =ROUND(O24+P24,2) -> 10000 | R24: =O24-I24 -> 0
A25: =ROW(A25)-15 -> 10 | B25: 一十 | C25: 南大尚诚 | D25: 44732 | E25: 10000 | F25: =E25-G25 -> 0 | G25: 10000 | H25: =G25-I25 -> 0 | I25: =IF(G25="120元/天",_xlfn.XLOOKUP(B25,'202604考勤'!B:B,'202604考勤'!AI:AI,"无")*120,IF(S25="转正",ROUND(G25/DAY(EOMONTH(T25,0))*(DAY(EOMONTH(T25,0))-DAY(T25)+1)+(G25*0.8)/DAY(EOMONTH(T25,0))*(DAY(T25)-1),2),IF(OR(AND(S25="入职",DAY(T25)=1),AND(S25="离职",T25=EOMONTH(T25,0))),G25,IF(OR(S25="离职",S25="入职"),ROUND(G25/21.75*_xlfn.XLOOKUP(B25,'202604考勤'!B:B,'202604考勤'!AI:AI,0),2),G25)))) -> 10000 | J25: 部门负责人 | K25: {=ROUND(_xlfn.IFS(OR(J25="南京大学",J25="BOSS",J25="实习生",J25="人力劳务"),I25,J25="部门负责人",I25*0.6,J25="员工",I25*0.7),2)} -> 6000 | L25: {=ROUND(_xlfn.IFS(OR(J25="南京大学",J25="BOSS",J25="实习生",J25="人力劳务"),I25*0,J25="部门负责人",I25*0.4,J25="员工",I25*0.3),2)} -> 4000 | M25: C | N25: {=ROUND(_xlfn.IFS(M25="A",L25*1.5,M25="B",L25*1.2,M25="C",L25*1,M25="D",L25*0.8,M25="E",L25*0.6,M25="无等级",L25*0),2)} -> 4000 | O25: =ROUND(K25+N25,2) -> 10000 | P25: 0 | Q25: =ROUND(O25+P25,2) -> 10000 | R25: =O25-I25 -> 0
A26: =ROW(A26)-15 -> 11 | B26: 一十一 | C26: 南大尚诚 | D26: 44743 | E26: 10000 | F26: =E26-G26 -> 0 | G26: 10000 | H26: =G26-I26 -> 0 | I26: =IF(G26="120元/天",_xlfn.XLOOKUP(B26,'202604考勤'!B:B,'202604考勤'!AI:AI,"无")*120,IF(S26="转正",ROUND(G26/DAY(EOMONTH(T26,0))*(DAY(EOMONTH(T26,0))-DAY(T26)+1)+(G26*0.8)/DAY(EOMONTH(T26,0))*(DAY(T26)-1),2),IF(OR(AND(S26="入职",DAY(T26)=1),AND(S26="离职",T26=EOMONTH(T26,0))),G26,IF(OR(S26="离职",S26="入职"),ROUND(G26/21.75*_xlfn.XLOOKUP(B26,'202604考勤'!B:B,'202604考勤'!AI:AI,0),2),G26)))) -> 10000 | J26: 员工 | K26: {=ROUND(_xlfn.IFS(OR(J26="南京大学",J26="BOSS",J26="实习生",J26="人力劳务"),I26,J26="部门负责人",I26*0.6,J26="员工",I26*0.7),2)} -> 7000 | L26: {=ROUND(_xlfn.IFS(OR(J26="南京大学",J26="BOSS",J26="实习生",J26="人力劳务"),I26*0,J26="部门负责人",I26*0.4,J26="员工",I26*0.3),2)} -> 3000 | M26: C | N26: {=ROUND(_xlfn.IFS(M26="A",L26*1.5,M26="B",L26*1.2,M26="C",L26*1,M26="D",L26*0.8,M26="E",L26*0.6,M26="无等级",L26*0),2)} -> 3000 | O26: =ROUND(K26+N26,2) -> 10000 | P26: 0 | Q26: =ROUND(O26+P26,2) -> 10000 | R26: =O26-I26 -> 0
A27: =ROW(A27)-15 -> 12 | B27: 一十二 | C27: 尚诚能源 | D27: 44746 | E27: 10000 | F27: =E27-G27 -> 0 | G27: 10000 | H27: =G27-I27 -> 0 | I27: =IF(G27="120元/天",_xlfn.XLOOKUP(B27,'202604考勤'!B:B,'202604考勤'!AI:AI,"无")*120,IF(S27="转正",ROUND(G27/DAY(EOMONTH(T27,0))*(DAY(EOMONTH(T27,0))-DAY(T27)+1)+(G27*0.8)/DAY(EOMONTH(T27,0))*(DAY(T27)-1),2),IF(OR(AND(S27="入职",DAY(T27)=1),AND(S27="离职",T27=EOMONTH(T27,0))),G27,IF(OR(S27="离职",S27="入职"),ROUND(G27/21.75*_xlfn.XLOOKUP(B27,'202604考勤'!B:B,'202604考勤'!AI:AI,0),2),G27)))) -> 10000 | J27: 部门负责人 | K27: {=ROUND(_xlfn.IFS(OR(J27="南京大学",J27="BOSS",J27="实习生",J27="人力劳务"),I27,J27="部门负责人",I27*0.6,J27="员工",I27*0.7),2)} -> 6000 | L27: {=ROUND(_xlfn.IFS(OR(J27="南京大学",J27="BOSS",J27="实习生",J27="人力劳务"),I27*0,J27="部门负责人",I27*0.4,J27="员工",I27*0.3),2)} -> 4000 | M27: C | N27: {=ROUND(_xlfn.IFS(M27="A",L27*1.5,M27="B",L27*1.2,M27="C",L27*1,M27="D",L27*0.8,M27="E",L27*0.6,M27="无等级",L27*0),2)} -> 4000 | O27: =ROUND(K27+N27,2) -> 10000 | P27: 0 | Q27: =ROUND(O27+P27,2) -> 10000 | R27: =O27-I27 -> 0
... A29: =ROW(A29)-15 -> 14 | B29: 一十四 | C29: 尚诚能源 | D29: 44774 | E29: 10000 | F29: =E29-G29 -> 0 | G29: 10000 | H29: =G29-I29 -> 0 | I29: =IF(G29="120元/天",_xlfn.XLOOKUP(B29,'202604考勤'!B:B,'202604考勤'!AI:AI,"无")*120,IF(S29="转正",ROUND(G29/DAY(EOMONTH(T29,0))*(DAY(EOMONTH(T29,0))-DAY(T29)+1)+(G29*0.8)/DAY(EOMONTH(T29,0))*(DAY(T29)-1),2),IF(OR(AND(S29="入职",DAY(T29)=1),AND(S29="离职",T29=EOMONTH(T29,0))),G29,IF(OR(S29="离职",S29="入职"),ROUND(G29/21.75*_xlfn.XLOOKUP(B29,'202604考勤'!B:B,'202604考勤'!AI:AI,0),2),G29)))) -> 10000 | J29: 员工 | K29: {=ROUND(_xlfn.IFS(OR(J29="南京大学",J29="BOSS",J29="实习生",J29="人力劳务"),I29,J29="部门负责人",I29*0.6,J29="员工",I29*0.7),2)} -> 7000 | L29: {=ROUND(_xlfn.IFS(OR(J29="南京大学",J29="BOSS",J29="实习生",J29="人力劳务"),I29*0,J29="部门负责人",I29*0.4,J29="员工",I29*0.3),2)} -> 3000 | M29: C | N29: {=ROUND(_xlfn.IFS(M29="A",L29*1.5,M29="B",L29*1.2,M29="C",L29*1,M29="D",L29*0.8,M29="E",L29*0.6,M29="无等级",L29*0),2)} -> 3000 | O29: =ROUND(K29+N29,2) -> 10000 | P29: 0 | Q29: =ROUND(O29+P29,2) -> 10000 | R29: =O29-I29 -> 0
A30: =ROW(A30)-15 -> 15 | B30: 一十五 | C30: 尚诚能源 | D30: 44774 | E30: 10000 | F30: =E30-G30 -> 0 | G30: 10000 | H30: =G30-I30 -> 0 | I30: =IF(G30="120元/天",_xlfn.XLOOKUP(B30,'202604考勤'!B:B,'202604考勤'!AI:AI,"无")*120,IF(S30="转正",ROUND(G30/DAY(EOMONTH(T30,0))*(DAY(EOMONTH(T30,0))-DAY(T30)+1)+(G30*0.8)/DAY(EOMONTH(T30,0))*(DAY(T30)-1),2),IF(OR(AND(S30="入职",DAY(T30)=1),AND(S30="离职",T30=EOMONTH(T30,0))),G30,IF(OR(S30="离职",S30="入职"),ROUND(G30/21.75*_xlfn.XLOOKUP(B30,'202604考勤'!B:B,'202604考勤'!AI:AI,0),2),G30)))) -> 10000 | J30: 员工 | K30: {=ROUND(_xlfn.IFS(OR(J30="南京大学",J30="BOSS",J30="实习生",J30="人力劳务"),I30,J30="部门负责人",I30*0.6,J30="员工",I30*0.7),2)} -> 7000 | L30: {=ROUND(_xlfn.IFS(OR(J30="南京大学",J30="BOSS",J30="实习生",J30="人力劳务"),I30*0,J30="部门负责人",I30*0.4,J30="员工",I30*0.3),2)} -> 3000 | M30: C | N30: {=ROUND(_xlfn.IFS(M30="A",L30*1.5,M30="B",L30*1.2,M30="C",L30*1,M30="D",L30*0.8,M30="E",L30*0.6,M30="无等级",L30*0),2)} -> 3000 | O30: =ROUND(K30+N30,2) -> 10000 | P30: =-(K30/21.75*1) -> -321.83908 | Q30: =ROUND(O30+P30,2) -> 9678.16 | R30: =O30-I30 -> 0 | S30: 事假 | T30: 1
A31: =ROW(A31)-15 -> 16 | B31: 一十六 | C31: 南大尚诚 | D31: 44774 | E31: 10000 | F31: =E31-G31 -> 0 | G31: 10000 | H31: =G31-I31 -> 0 | I31: =IF(G31="120元/天",_xlfn.XLOOKUP(B31,'202604考勤'!B:B,'202604考勤'!AI:AI,"无")*120,IF(S31="转正",ROUND(G31/DAY(EOMONTH(T31,0))*(DAY(EOMONTH(T31,0))-DAY(T31)+1)+(G31*0.8)/DAY(EOMONTH(T31,0))*(DAY(T31)-1),2),IF(OR(AND(S31="入职",DAY(T31)=1),AND(S31="离职",T31=EOMONTH(T31,0))),G31,IF(OR(S31="离职",S31="入职"),ROUND(G31/21.75*_xlfn.XLOOKUP(B31,'202604考勤'!B:B,'202604考勤'!AI:AI,0),2),G31)))) -> 10000 | J31: 员工 | K31: {=ROUND(_xlfn.IFS(OR(J31="南京大学",J31="BOSS",J31="实习生",J31="人力劳务"),I31,J31="部门负责人",I31*0.6,J31="员工",I31*0.7),2)} -> 7000 | L31: {=ROUND(_xlfn.IFS(OR(J31="南京大学",J31="BOSS",J31="实习生",J31="人力劳务"),I31*0,J31="部门负责人",I31*0.4,J31="员工",I31*0.3),2)} -> 3000 | M31: C | N31: {=ROUND(_xlfn.IFS(M31="A",L31*1.5,M31="B",L31*1.2,M31="C",L31*1,M31="D",L31*0.8,M31="E",L31*0.6,M31="无等级",L31*0),2)} -> 3000 | O31: =ROUND(K31+N31,2) -> 10000 | P31: 0 | Q31: =ROUND(O31+P31,2) -> 10000 | R31: =O31-I31 -> 0
A32: =ROW(A32)-15 -> 17 | B32: 一十七 | C32: 基石 | D32: 44774 | E32: 10000 | F32: =E32-G32 -> 0 | G32: 10000 | H32: =G32-I32 -> 0 | I32: =IF(G32="120元/天",_xlfn.XLOOKUP(B32,'202604考勤'!B:B,'202604考勤'!AI:AI,"无")*120,IF(S32="转正",ROUND(G32/DAY(EOMONTH(T32,0))*(DAY(EOMONTH(T32,0))-DAY(T32)+1)+(G32*0.8)/DAY(EOMONTH(T32,0))*(DAY(T32)-1),2),IF(OR(AND(S32="入职",DAY(T32)=1),AND(S32="离职",T32=EOMONTH(T32,0))),G32,IF(OR(S32="离职",S32="入职"),ROUND(G32/21.75*_xlfn.XLOOKUP(B32,'202604考勤'!B:B,'202604考勤'!AI:AI,0),2),G32)))) -> 10000 | J32: 部门负责人 | K32: {=ROUND(_xlfn.IFS(OR(J32="南京大学",J32="BOSS",J32="实习生",J32="人力劳务"),I32,J32="部门负责人",I32*0.6,J32="员工",I32*0.7),2)} -> 6000 | L32: {=ROUND(_xlfn.IFS(OR(J32="南京大学",J32="BOSS",J32="实习生",J32="人力劳务"),I32*0,J32="部门负责人",I32*0.4,J32="员工",I32*0.3),2)} -> 4000 | M32: C | N32: {=ROUND(_xlfn.IFS(M32="A",L32*1.5,M32="B",L32*1.2,M32="C",L32*1,M32="D",L32*0.8,M32="E",L32*0.6,M32="无等级",L32*0),2)} -> 4000 | O32: =ROUND(K32+N32,2) -> 10000 | P32: 0 | Q32: =ROUND(O32+P32,2) -> 10000 | R32: =O32-I32 -> 0
A33: =ROW(A33)-15 -> 18 | B33: 一十八 | C33: 南大尚诚 | D33: 44781 | E33: 10000 | F33: =E33-G33 -> 0 | G33: 10000 | H33: =G33-I33 -> 0 | I33: =IF(G33="120元/天",_xlfn.XLOOKUP(B33,'202604考勤'!B:B,'202604考勤'!AI:AI,"无")*120,IF(S33="转正",ROUND(G33/DAY(EOMONTH(T33,0))*(DAY(EOMONTH(T33,0))-DAY(T33)+1)+(G33*0.8)/DAY(EOMONTH(T33,0))*(DAY(T33)-1),2),IF(OR(AND(S33="入职",DAY(T33)=1),AND(S33="离职",T33=EOMONTH(T33,0))),G33,IF(OR(S33="离职",S33="入职"),ROUND(G33/21.75*_xlfn.XLOOKUP(B33,'202604考勤'!B:B,'202604考勤'!AI:AI,0),2),G33)))) -> 10000 | J33: 员工 | K33: {=ROUND(_xlfn.IFS(OR(J33="南京大学",J33="BOSS",J33="实习生",J33="人力劳务"),I33,J33="部门负责人",I33*0.6,J33="员工",I33*0.7),2)} -> 7000 | L33: {=ROUND(_xlfn.IFS(OR(J33="南京大学",J33="BOSS",J33="实习生",J33="人力劳务"),I33*0,J33="部门负责人",I33*0.4,J33="员工",I33*0.3),2)} -> 3000 | M33: C | N33: {=ROUND(_xlfn.IFS(M33="A",L33*1.5,M33="B",L33*1.2,M33="C",L33*1,M33="D",L33*0.8,M33="E",L33*0.6,M33="无等级",L33*0),2)} -> 3000 | O33: =ROUND(K33+N33,2) -> 10000 | P33: 0 | Q33: =ROUND(O33+P33,2) -> 10000 | R33: =O33-I33 -> 0
A34: =ROW(A34)-15 -> 19 | B34: 一十九 | C34: 南大尚诚 | D34: 44788 | E34: 10000 | F34: =E34-G34 -> 0 | G34: 10000 | H34: =G34-I34 -> 0 | I34: =IF(G34="120元/天",_xlfn.XLOOKUP(B34,'202604考勤'!B:B,'202604考勤'!AI:AI,"无")*120,IF(S34="转正",ROUND(G34/DAY(EOMONTH(T34,0))*(DAY(EOMONTH(T34,0))-DAY(T34)+1)+(G34*0.8)/DAY(EOMONTH(T34,0))*(DAY(T34)-1),2),IF(OR(AND(S34="入职",DAY(T34)=1),AND(S34="离职",T34=EOMONTH(T34,0))),G34,IF(OR(S34="离职",S34="入职"),ROUND(G34/21.75*_xlfn.XLOOKUP(B34,'202604考勤'!B:B,'202604考勤'!AI:AI,0),2),G34)))) -> 10000 | J34: 员工 | K34: {=ROUND(_xlfn.IFS(OR(J34="南京大学",J34="BOSS",J34="实习生",J34="人力劳务"),I34,J34="部门负责人",I34*0.6,J34="员工",I34*0.7),2)} -> 7000 | L34: {=ROUND(_xlfn.IFS(OR(J34="南京大学",J34="BOSS",J34="实习生",J34="人力劳务"),I34*0,J34="部门负责人",I34*0.4,J34="员工",I34*0.3),2)} -> 3000 | M34: C | N34: {=ROUND(_xlfn.IFS(M34="A",L34*1.5,M34="B",L34*1.2,M34="C",L34*1,M34="D",L34*0.8,M34="E",L34*0.6,M34="无等级",L34*0),2)} -> 3000 | O34: =ROUND(K34+N34,2) -> 10000 | P34: 0 | Q34: =ROUND(O34+P34,2) -> 10000 | R34: =O34-I34 -> 0
A35: =ROW(A35)-15 -> 20 | B35: 二十 | C35: 南大尚诚 | D35: 45047 | E35: 10000 | F35: =E35-G35 -> 0 | G35: 10000 | H35: =G35-I35 -> 0 | I35: =IF(G35="120元/天",_xlfn.XLOOKUP(B35,'202604考勤'!B:B,'202604考勤'!AI:AI,"无")*120,IF(S35="转正",ROUND(G35/DAY(EOMONTH(T35,0))*(DAY(EOMONTH(T35,0))-DAY(T35)+1)+(G35*0.8)/DAY(EOMONTH(T35,0))*(DAY(T35)-1),2),IF(OR(AND(S35="入职",DAY(T35)=1),AND(S35="离职",T35=EOMONTH(T35,0))),G35,IF(OR(S35="离职",S35="入职"),ROUND(G35/21.75*_xlfn.XLOOKUP(B35,'202604考勤'!B:B,'202604考勤'!AI:AI,0),2),G35)))) -> 10000 | J35: 员工 | K35: {=ROUND(_xlfn.IFS(OR(J35="南京大学",J35="BOSS",J35="实习生",J35="人力劳务"),I35,J35="部门负责人",I35*0.6,J35="员工",I35*0.7),2)} -> 7000 | L35: {=ROUND(_xlfn.IFS(OR(J35="南京大学",J35="BOSS",J35="实习生",J35="人力劳务"),I35*0,J35="部门负责人",I35*0.4,J35="员工",I35*0.3),2)} -> 3000 | M35: C | N35: {=ROUND(_xlfn.IFS(M35="A",L35*1.5,M35="B",L35*1.2,M35="C",L35*1,M35="D",L35*0.8,M35="E",L35*0.6,M35="无等级",L35*0),2)} -> 3000 | O35: =ROUND(K35+N35,2) -> 10000 | P35: 0 | Q35: =ROUND(O35+P35,2) -> 10000 | R35: =O35-I35 -> 0
A36: =ROW(A36)-15 -> 21 | B36: 二十一 | C36: 尚诚能源 | D36: 44805 | E36: 10000 | F36: =E36-G36 -> 0 | G36: 10000 | H36: =G36-I36 -> 0 | I36: =IF(G36="120元/天",_xlfn.XLOOKUP(B36,'202604考勤'!B:B,'202604考勤'!AI:AI,"无")*120,IF(S36="转正",ROUND(G36/DAY(EOMONTH(T36,0))*(DAY(EOMONTH(T36,0))-DAY(T36)+1)+(G36*0.8)/DAY(EOMONTH(T36,0))*(DAY(T36)-1),2),IF(OR(AND(S36="入职",DAY(T36)=1),AND(S36="离职",T36=EOMONTH(T36,0))),G36,IF(OR(S36="离职",S36="入职"),ROUND(G36/21.75*_xlfn.XLOOKUP(B36,'202604考勤'!B:B,'202604考勤'!AI:AI,0),2),G36)))) -> 10000 | J36: 员工 | K36: {=ROUND(_xlfn.IFS(OR(J36="南京大学",J36="BOSS",J36="实习生",J36="人力劳务"),I36,J36="部门负责人",I36*0.6,J36="员工",I36*0.7),2)} -> 7000 | L36: {=ROUND(_xlfn.IFS(OR(J36="南京大学",J36="BOSS",J36="实习生",J36="人力劳务"),I36*0,J36="部门负责人",I36*0.4,J36="员工",I36*0.3),2)} -> 3000 | M36: C | N36: {=ROUND(_xlfn.IFS(M36="A",L36*1.5,M36="B",L36*1.2,M36="C",L36*1,M36="D",L36*0.8,M36="E",L36*0.6,M36="无等级",L36*0),2)} -> 3000 | O36: =ROUND(K36+N36,2) -> 10000 | P36: 0 | Q36: =ROUND(O36+P36,2) -> 10000 | R36: =O36-I36 -> 0
A37: =ROW(A37)-15 -> 22 | B37: 二十二 | C37: 南大尚诚 | D37: 44805 | E37: 10000 | F37: =E37-G37 -> 0 | G37: 10000 | H37: =G37-I37 -> 0 | I37: =IF(G37="120元/天",_xlfn.XLOOKUP(B37,'202604考勤'!B:B,'202604考勤'!AI:AI,"无")*120,IF(S37="转正",ROUND(G37/DAY(EOMONTH(T37,0))*(DAY(EOMONTH(T37,0))-DAY(T37)+1)+(G37*0.8)/DAY(EOMONTH(T37,0))*(DAY(T37)-1),2),IF(OR(AND(S37="入职",DAY(T37)=1),AND(S37="离职",T37=EOMONTH(T37,0))),G37,IF(OR(S37="离职",S37="入职"),ROUND(G37/21.75*_xlfn.XLOOKUP(B37,'202604考勤'!B:B,'202604考勤'!AI:AI,0),2),G37)))) -> 10000 | J37: 员工 | K37: {=ROUND(_xlfn.IFS(OR(J37="南京大学",J37="BOSS",J37="实习生",J37="人力劳务"),I37,J37="部门负责人",I37*0.6,J37="员工",I37*0.7),2)} -> 7000 | L37: {=ROUND(_xlfn.IFS(OR(J37="南京大学",J37="BOSS",J37="实习生",J37="人力劳务"),I37*0,J37="部门负责人",I37*0.4,J37="员工",I37*0.3),2)} -> 3000 | M37: C | N37: {=ROUND(_xlfn.IFS(M37="A",L37*1.5,M37="B",L37*1.2,M37="C",L37*1,M37="D",L37*0.8,M37="E",L37*0.6,M37="无等级",L37*0),2)} -> 3000 | O37: =ROUND(K37+N37,2) -> 10000 | P37: 0 | Q37: =ROUND(O37+P37,2) -> 10000 | R37: =O37-I37 -> 0
A38: =ROW(A38)-15 -> 23 | B38: 二十三 | C38: 南大尚诚 | D38: 44811 | E38: 10000 | F38: =E38-G38 -> 0 | G38: 10000 | H38: =G38-I38 -> 0 | I38: =IF(G38="120元/天",_xlfn.XLOOKUP(B38,'202604考勤'!B:B,'202604考勤'!AI:AI,"无")*120,IF(S38="转正",ROUND(G38/DAY(EOMONTH(T38,0))*(DAY(EOMONTH(T38,0))-DAY(T38)+1)+(G38*0.8)/DAY(EOMONTH(T38,0))*(DAY(T38)-1),2),IF(OR(AND(S38="入职",DAY(T38)=1),AND(S38="离职",T38=EOMONTH(T38,0))),G38,IF(OR(S38="离职",S38="入职"),ROUND(G38/21.75*_xlfn.XLOOKUP(B38,'202604考勤'!B:B,'202604考勤'!AI:AI,0),2),G38)))) -> 10000 | J38: 员工 | K38: {=ROUND(_xlfn.IFS(OR(J38="南京大学",J38="BOSS",J38="实习生",J38="人力劳务"),I38,J38="部门负责人",I38*0.6,J38="员工",I38*0.7),2)} -> 7000 | L38: {=ROUND(_xlfn.IFS(OR(J38="南京大学",J38="BOSS",J38="实习生",J38="人力劳务"),I38*0,J38="部门负责人",I38*0.4,J38="员工",I38*0.3),2)} -> 3000 | M38: C | N38: {=ROUND(_xlfn.IFS(M38="A",L38*1.5,M38="B",L38*1.2,M38="C",L38*1,M38="D",L38*0.8,M38="E",L38*0.6,M38="无等级",L38*0),2)} -> 3000 | O38: =ROUND(K38+N38,2) -> 10000 | P38: 0 | Q38: =ROUND(O38+P38,2) -> 10000 | R38: =O38-I38 -> 0
A39: =ROW(A39)-15 -> 24 | B39: 二十四 | C39: 南大尚诚 | D39: 44817 | E39: 10000 | F39: =E39-G39 -> 0 | G39: 10000 | H39: =G39-I39 -> 0 | I39: =IF(G39="120元/天",_xlfn.XLOOKUP(B39,'202604考勤'!B:B,'202604考勤'!AI:AI,"无")*120,IF(S39="转正",ROUND(G39/DAY(EOMONTH(T39,0))*(DAY(EOMONTH(T39,0))-DAY(T39)+1)+(G39*0.8)/DAY(EOMONTH(T39,0))*(DAY(T39)-1),2),IF(OR(AND(S39="入职",DAY(T39)=1),AND(S39="离职",T39=EOMONTH(T39,0))),G39,IF(OR(S39="离职",S39="入职"),ROUND(G39/21.75*_xlfn.XLOOKUP(B39,'202604考勤'!B:B,'202604考勤'!AI:AI,0),2),G39)))) -> 10000 | J39: 员工 | K39: {=ROUND(_xlfn.IFS(OR(J39="南京大学",J39="BOSS",J39="实习生",J39="人力劳务"),I39,J39="部门负责人",I39*0.6,J39="员工",I39*0.7),2)} -> 7000 | L39: {=ROUND(_xlfn.IFS(OR(J39="南京大学",J39="BOSS",J39="实习生",J39="人力劳务"),I39*0,J39="部门负责人",I39*0.4,J39="员工",I39*0.3),2)} -> 3000 | M39: C | N39: {=ROUND(_xlfn.IFS(M39="A",L39*1.5,M39="B",L39*1.2,M39="C",L39*1,M39="D",L39*0.8,M39="E",L39*0.6,M39="无等级",L39*0),2)} -> 3000 | O39: =ROUND(K39+N39,2) -> 10000 | P39: 0 | Q39: =ROUND(O39+P39,2) -> 10000 | R39: =O39-I39 -> 0
A40: =ROW(A40)-15 -> 25 | B40: 二十五 | C40: 南大尚诚 | D40: 44823 | E40: 10000 | F40: =E40-G40 -> 0 | G40: 10000 | H40: =G40-I40 -> 0 | I40: =IF(G40="120元/天",_xlfn.XLOOKUP(B40,'202604考勤'!B:B,'202604考勤'!AI:AI,"无")*120,IF(S40="转正",ROUND(G40/DAY(EOMONTH(T40,0))*(DAY(EOMONTH(T40,0))-DAY(T40)+1)+(G40*0.8)/DAY(EOMONTH(T40,0))*(DAY(T40)-1),2),IF(OR(AND(S40="入职",DAY(T40)=1),AND(S40="离职",T40=EOMONTH(T40,0))),G40,IF(OR(S40="离职",S40="入职"),ROUND(G40/21.75*_xlfn.XLOOKUP(B40,'202604考勤'!B:B,'202604考勤'!AI:AI,0),2),G40)))) -> 10000 | J40: 员工 | K40: {=ROUND(_xlfn.IFS(OR(J40="南京大学",J40="BOSS",J40="实习生",J40="人力劳务"),I40,J40="部门负责人",I40*0.6,J40="员工",I40*0.7),2)} -> 7000 | L40: {=ROUND(_xlfn.IFS(OR(J40="南京大学",J40="BOSS",J40="实习生",J40="人力劳务"),I40*0,J40="部门负责人",I40*0.4,J40="员工",I40*0.3),2)} -> 3000 | M40: B | N40: {=ROUND(_xlfn.IFS(M40="A",L40*1.5,M40="B",L40*1.2,M40="C",L40*1,M40="D",L40*0.8,M40="E",L40*0.6,M40="无等级",L40*0),2)} -> 3600 | O40: =ROUND(K40+N40,2) -> 10600 | P40: 0 | Q40: =ROUND(O40+P40,2) -> 10600 | R40: =O40-I40 -> 600
A41: =ROW(A41)-15 -> 26 | B41: 二十六 | C41: 南大尚诚 | D41: 44823 | E41: 10000 | F41: =E41-G41 -> 0 | G41: 10000 | H41: =G41-I41 -> 0 | I41: =IF(G41="120元/天",_xlfn.XLOOKUP(B41,'202604考勤'!B:B,'202604考勤'!AI:AI,"无")*120,IF(S41="转正",ROUND(G41/DAY(EOMONTH(T41,0))*(DAY(EOMONTH(T41,0))-DAY(T41)+1)+(G41*0.8)/DAY(EOMONTH(T41,0))*(DAY(T41)-1),2),IF(OR(AND(S41="入职",DAY(T41)=1),AND(S41="离职",T41=EOMONTH(T41,0))),G41,IF(OR(S41="离职",S41="入职"),ROUND(G41/21.75*_xlfn.XLOOKUP(B41,'202604考勤'!B:B,'202604考勤'!AI:AI,0),2),G41)))) -> 10000 | J41: 员工 | K41: {=ROUND(_xlfn.IFS(OR(J41="南京大学",J41="BOSS",J41="实习生",J41="人力劳务"),I41,J41="部门负责人",I41*0.6,J41="员工",I41*0.7),2)} -> 7000 | L41: {=ROUND(_xlfn.IFS(OR(J41="南京大学",J41="BOSS",J41="实习生",J41="人力劳务"),I41*0,J41="部门负责人",I41*0.4,J41="员工",I41*0.3),2)} -> 3000 | M41: C | N41: {=ROUND(_xlfn.IFS(M41="A",L41*1.5,M41="B",L41*1.2,M41="C",L41*1,M41="D",L41*0.8,M41="E",L41*0.6,M41="无等级",L41*0),2)} -> 3000 | O41: =ROUND(K41+N41,2) -> 10000 | P41: 0 | Q41: =ROUND(O41+P41,2) -> 10000 | R41: =O41-I41 -> 0
...

Sheet 马骏老师202604
A1: 202604劳务费明细表
A2: 姓名 | B2: 公司 | C2: 含税劳务金额 | D2: 不含税劳务金额 | E2: 税额 | F2: 应纳税所得额 | G2: 代扣劳务个税 | H2: 实发金额 | P2: 起薪时间
A3: 马骏 | B3: 尚诚能源 | C3: 8000 | D3: =C3-E3 -> 7920.79 | E3: 79.21 | F3: =D3*0.8 -> 6336.632 | G3: =F3*0.2 -> 1267.3264 | H3: =C3-G3 -> 6732.6736 | I3: 南大老师税前8000 520102198009074214 18951991733 | P3: 45108
A4: 总经理： 财务负责人： 制表人：

Sheet 202604工资明细表（尚诚能源）
A1: 202604工资表
A2: 序号 | B2: 姓名 | C2: 起薪时间 | D2: 月薪基数 | E2: 系数 | F2: 实际应发工资 | G2: 基本养老保险费 | H2: 失业保险费 | I2: 基本医疗保险费 | J2: 大病保险费 | K2: 社保合计 | L2: 住房公积金 | M2: 专项累计扣除 | N2: 继续教育 | O2: 三岁以下婴幼儿 | P2: 子女教育 | Q2: 住房贷款利息 | R2: 住房租金 | S2: 赡养老人 | T2: 专项附加扣除合计 | U2: 税前扣除项目合计 | V2: 上月累计专项扣除合计 | W2: 累计扣除项目合计 | X2: 上月累计收入 | Y2: 累计收入 | Z2: 减除费用 | AA2: 税前工资 | AB2: 累计计税部分 | AC2: 累计个税 | AD2: 上月累计个税 | AE2: 本月个税 | AF2: 实发工资
A3: =ROW(A3)-2 -> 1 | B3: {=_xlfn.LET(_xlpm.B列,INDIRECT("'"&A1&"'!B3:B190"),_xlpm.C列,INDIRECT("'"&A1&"'!C3:C190"),_xlfn._xlws.FILTER(_xlpm.B列,(_xlpm.C列="尚诚能源")*(_xlpm.B列<>"")))} -> 一 | C3: {=_xlfn.XLOOKUP(B3,INDIRECT("'"&$A$1&"'!B:B"),INDIRECT("'"&$A$1&"'!D:D"),"人员不存在",0,1)} -> 44713 | D3: {=_xlfn.XLOOKUP(B3,INDIRECT("'"&$A$1&"'!B:B"),INDIRECT("'"&$A$1&"'!G:G"),"人员不存在",0,1)} -> 10000 | E3: =IFERROR(F3/D3,0) -> 1 | F3: {=_xlfn.XLOOKUP(B3,INDIRECT("'"&$A$1&"'!B:B"),INDIRECT("'"&$A$1&"'!Q:Q"),"人员不存在",0,1)} -> 10000 | G3: {=SUMIF(INDIRECT("'"&$G$47&"'!C5:C"&IFERROR(MATCH(TRUE,ISBLANK(INDIRECT("'"&$G$47&"'!C5:C500")),0)+4,500)),B3,INDIRECT("'"&$G$47&"'!K5:K"&IFERROR(MATCH(TRUE,ISBLANK(INDIRECT("'"&$G$47&"'!C5:C500")),0)+4,500)))} -> 0 | H3: {=SUMIF(INDIRECT("'"&$G$47&"'!C5:C"&IFERROR(MATCH(TRUE,ISBLANK(INDIRECT("'"&$G$47&"'!C5:C500")),0)+4,500)),B3,INDIRECT("'"&$G$47&"'!L5:L"&IFERROR(MATCH(TRUE,ISBLANK(INDIRECT("'"&$G$47&"'!C5:C500")),0)+4,500)))} -> 0 | I3: {=SUMIF(INDIRECT("'"&$G$47&"'!C5:C"&IFERROR(MATCH(TRUE,ISBLANK(INDIRECT("'"&$G$47&"'!C5:C500")),0)+4,500)),B3,INDIRECT("'"&$G$47&"'!M5:M"&IFERROR(MATCH(TRUE,ISBLANK(INDIRECT("'"&$G$47&"'!C5:C500")),0)+4,500)))} -> 0 | J3: {=SUMIF(INDIRECT("'"&$G$47&"'!C5:C"&IFERROR(MATCH(TRUE,ISBLANK(INDIRECT("'"&$G$47&"'!C5:C500")),0)+4,500)),B3,INDIRECT("'"&$G$47&"'!N5:N"&IFERROR(MATCH(TRUE,ISBLANK(INDIRECT("'"&$G$47&"'!C5:C500")),0)+4,500)))} -> 0 | K3: =SUM(G3:J3) -> 0 | L3: {=IFERROR(_xlfn.XLOOKUP(B3,INDIRECT("'"&$I$47&"'!B:B"),INDIRECT("'"&$I$47&"'!E:E"),0),0)} -> 0 | M3: =ROUND(SUM(K3:L3),2) -> 0 | N3: {=IFERROR(_xlfn.XLOOKUP(B3,INDIRECT("'"&$M$47&"'!B:B"),INDIRECT("'"&$M$47&"'!AC:AC"),0),0)} -> 0 | O3: {=IFERROR(_xlfn.XLOOKUP(B3,INDIRECT("'"&$M$47&"'!B:B"),INDIRECT("'"&$M$47&"'!AG:AG"),0),0)} -> 0 | P3: {=IFERROR(_xlfn.XLOOKUP(B3,INDIRECT("'"&$M$47&"'!B:B"),INDIRECT("'"&$M$47&"'!AB:AB"),0),0)} -> 0 | Q3: {=IFERROR(_xlfn.XLOOKUP(B3,INDIRECT("'"&$M$47&"'!B:B"),INDIRECT("'"&$M$47&"'!AD:AD"),0),0)} -> 0 | R3: {=IFERROR(_xlfn.XLOOKUP(B3,INDIRECT("'"&$M$47&"'!B:B"),INDIRECT("'"&$M$47&"'!AE:AE"),0),0)} -> 0 | S3: {=IFERROR(_xlfn.XLOOKUP(B3,INDIRECT("'"&$M$47&"'!B:B"),INDIRECT("'"&$M$47&"'!AF:AF"),0),0)} -> 0 | T3: =SUM(N3:S3) -> 0 | U3: =ROUND(SUM(M3:S3),2) -> 0 | V3: {=IFERROR(_xlfn.XLOOKUP(B3,INDIRECT("'"&$K$47&"'!B:B"),INDIRECT("'"&$K$47&"'!Y:Y"),0),0)} -> 0 | W3: =U3+V3 -> 0 | X3: {=IFERROR(_xlfn.XLOOKUP(B3,INDIRECT("'"&$K$47&"'!B:B"),INDIRECT("'"&$K$47&"'!Z:Z"),0),0)} -> 0 | Y3: =F3+X3 -> 10000 | Z3: {=IFERROR(_xlfn.LET(_xlpm.v,_xlfn.XLOOKUP(B3,INDIRECT("'"&$K$47&"'!B:B"),INDIRECT("'"&$K$47&"'!AA:AA"),0),IF(_xlpm.v=60000,60000,_xlpm.v+5000)),0)} -> 0 | AA3: =ROUND(F3-M3,2) -> 10000 | AB3: =IF(ROUND(Y3-W3-Z3,2)>0,ROUND(Y3-W3-Z3,2),0) -> 10000 | AC3: =ROUND(IF(AB3>960000,AB3*0.45-181920,IF(AB3>660000,AB3*0.35-85920,IF(AB3>420000,AB3*0.3-52920,IF(AB3>300000,AB3*0.25-31920,IF(AB3>144000,AB3*0.2-16920,IF(AB3>36000,AB3*0.1-2520,IF(AB3>0,AB3*0.03,0))))))),2) -> 300 | AD3: {=IFERROR(_xlfn.XLOOKUP(B3,INDIRECT("'"&$K$47&"'!B:B"),INDIRECT("'"&$K$47&"'!AD:AD"),0),0)} -> 0 | AE3: =ROUND(MAX(AC3-AD3,0),2) -> 300 | AF3: =ROUND(AA3-AE3,2) -> 9700
A4: =ROW(A4)-2 -> 2 | B4: 二 | C4: {=_xlfn.XLOOKUP(B4,INDIRECT("'"&$A$1&"'!B:B"),INDIRECT("'"&$A$1&"'!D:D"),"人员不存在",0,1)} -> 44805 | D4: {=_xlfn.XLOOKUP(B4,INDIRECT("'"&$A$1&"'!B:B"),INDIRECT("'"&$A$1&"'!G:G"),"人员不存在",0,1)} -> 10000 | E4: =IFERROR(F4/D4,0) -> 1 | F4: {=_xlfn.XLOOKUP(B4,INDIRECT("'"&$A$1&"'!B:B"),INDIRECT("'"&$A$1&"'!Q:Q"),"人员不存在",0,1)} -> 10000 | G4: {=SUMIF(INDIRECT("'"&$G$47&"'!C5:C"&IFERROR(MATCH(TRUE,ISBLANK(INDIRECT("'"&$G$47&"'!C5:C500")),0)+4,500)),B4,INDIRECT("'"&$G$47&"'!K5:K"&IFERROR(MATCH(TRUE,ISBLANK(INDIRECT("'"&$G$47&"'!C5:C500")),0)+4,500)))} -> 0 | H4: {=SUMIF(INDIRECT("'"&$G$47&"'!C5:C"&IFERROR(MATCH(TRUE,ISBLANK(INDIRECT("'"&$G$47&"'!C5:C500")),0)+4,500)),B4,INDIRECT("'"&$G$47&"'!L5:L"&IFERROR(MATCH(TRUE,ISBLANK(INDIRECT("'"&$G$47&"'!C5:C500")),0)+4,500)))} -> 0 | I4: {=SUMIF(INDIRECT("'"&$G$47&"'!C5:C"&IFERROR(MATCH(TRUE,ISBLANK(INDIRECT("'"&$G$47&"'!C5:C500")),0)+4,500)),B4,INDIRECT("'"&$G$47&"'!M5:M"&IFERROR(MATCH(TRUE,ISBLANK(INDIRECT("'"&$G$47&"'!C5:C500")),0)+4,500)))} -> 0 | J4: {=SUMIF(INDIRECT("'"&$G$47&"'!C5:C"&IFERROR(MATCH(TRUE,ISBLANK(INDIRECT("'"&$G$47&"'!C5:C500")),0)+4,500)),B4,INDIRECT("'"&$G$47&"'!N5:N"&IFERROR(MATCH(TRUE,ISBLANK(INDIRECT("'"&$G$47&"'!C5:C500")),0)+4,500)))} -> 0 | K4: =SUM(G4:J4) -> 0 | L4: {=IFERROR(_xlfn.XLOOKUP(B4,INDIRECT("'"&$I$47&"'!B:B"),INDIRECT("'"&$I$47&"'!E:E"),0),0)} -> 0 | M4: =ROUND(SUM(K4:L4),2) -> 0 | N4: {=IFERROR(_xlfn.XLOOKUP(B4,INDIRECT("'"&$M$47&"'!B:B"),INDIRECT("'"&$M$47&"'!AC:AC"),0),0)} -> 0 | O4: {=IFERROR(_xlfn.XLOOKUP(B4,INDIRECT("'"&$M$47&"'!B:B"),INDIRECT("'"&$M$47&"'!AG:AG"),0),0)} -> 0 | P4: {=IFERROR(_xlfn.XLOOKUP(B4,INDIRECT("'"&$M$47&"'!B:B"),INDIRECT("'"&$M$47&"'!AB:AB"),0),0)} -> 0 | Q4: {=IFERROR(_xlfn.XLOOKUP(B4,INDIRECT("'"&$M$47&"'!B:B"),INDIRECT("'"&$M$47&"'!AD:AD"),0),0)} -> 0 | R4: {=IFERROR(_xlfn.XLOOKUP(B4,INDIRECT("'"&$M$47&"'!B:B"),INDIRECT("'"&$M$47&"'!AE:AE"),0),0)} -> 0 | S4: {=IFERROR(_xlfn.XLOOKUP(B4,INDIRECT("'"&$M$47&"'!B:B"),INDIRECT("'"&$M$47&"'!AF:AF"),0),0)} -> 0 | T4: =SUM(N4:S4) -> 0 | U4: =ROUND(SUM(M4:S4),2) -> 0 | V4: {=IFERROR(_xlfn.XLOOKUP(B4,INDIRECT("'"&$K$47&"'!B:B"),INDIRECT("'"&$K$47&"'!Y:Y"),0),0)} -> 0 | W4: =U4+V4 -> 0 | X4: {=IFERROR(_xlfn.XLOOKUP(B4,INDIRECT("'"&$K$47&"'!B:B"),INDIRECT("'"&$K$47&"'!Z:Z"),0),0)} -> 0 | Y4: =F4+X4 -> 10000 | Z4: 0 | AA4: =ROUND(F4-M4,2) -> 10000 | AB4: =IF(ROUND(Y4-W4-Z4,2)>0,ROUND(Y4-W4-Z4,2),0) -> 10000 | AC4: =ROUND(IF(AB4>960000,AB4*0.45-181920,IF(AB4>660000,AB4*0.35-85920,IF(AB4>420000,AB4*0.3-52920,IF(AB4>300000,AB4*0.25-31920,IF(AB4>144000,AB4*0.2-16920,IF(AB4>36000,AB4*0.1-2520,IF(AB4>0,AB4*0.03,0))))))),2) -> 300 | AD4: {=IFERROR(_xlfn.XLOOKUP(B4,INDIRECT("'"&$K$47&"'!B:B"),INDIRECT("'"&$K$47&"'!AD:AD"),0),0)} -> 0 | AE4: =ROUND(MAX(AC4-AD4,0),2) -> 300 | AF4: =ROUND(AA4-AE4,2) -> 9700
A5: =ROW(A5)-2 -> 3 | B5: 三 | C5: {=_xlfn.XLOOKUP(B5,INDIRECT("'"&$A$1&"'!B:B"),INDIRECT("'"&$A$1&"'!D:D"),"人员不存在",0,1)} -> 44958 | D5: {=_xlfn.XLOOKUP(B5,INDIRECT("'"&$A$1&"'!B:B"),INDIRECT("'"&$A$1&"'!G:G"),"人员不存在",0,1)} -> 10000 | E5: =IFERROR(F5/D5,0) -> 1 | F5: {=_xlfn.XLOOKUP(B5,INDIRECT("'"&$A$1&"'!B:B"),INDIRECT("'"&$A$1&"'!Q:Q"),"人员不存在",0,1)} -> 10000 | G5: {=SUMIF(INDIRECT("'"&$G$47&"'!C5:C"&IFERROR(MATCH(TRUE,ISBLANK(INDIRECT("'"&$G$47&"'!C5:C500")),0)+4,500)),B5,INDIRECT("'"&$G$47&"'!K5:K"&IFERROR(MATCH(TRUE,ISBLANK(INDIRECT("'"&$G$47&"'!C5:C500")),0)+4,500)))} -> 0 | H5: {=SUMIF(INDIRECT("'"&$G$47&"'!C5:C"&IFERROR(MATCH(TRUE,ISBLANK(INDIRECT("'"&$G$47&"'!C5:C500")),0)+4,500)),B5,INDIRECT("'"&$G$47&"'!L5:L"&IFERROR(MATCH(TRUE,ISBLANK(INDIRECT("'"&$G$47&"'!C5:C500")),0)+4,500)))} -> 0 | I5: {=SUMIF(INDIRECT("'"&$G$47&"'!C5:C"&IFERROR(MATCH(TRUE,ISBLANK(INDIRECT("'"&$G$47&"'!C5:C500")),0)+4,500)),B5,INDIRECT("'"&$G$47&"'!M5:M"&IFERROR(MATCH(TRUE,ISBLANK(INDIRECT("'"&$G$47&"'!C5:C500")),0)+4,500)))} -> 0 | J5: {=SUMIF(INDIRECT("'"&$G$47&"'!C5:C"&IFERROR(MATCH(TRUE,ISBLANK(INDIRECT("'"&$G$47&"'!C5:C500")),0)+4,500)),B5,INDIRECT("'"&$G$47&"'!N5:N"&IFERROR(MATCH(TRUE,ISBLANK(INDIRECT("'"&$G$47&"'!C5:C500")),0)+4,500)))} -> 0 | K5: =SUM(G5:J5) -> 0 | L5: {=IFERROR(_xlfn.XLOOKUP(B5,INDIRECT("'"&$I$47&"'!B:B"),INDIRECT("'"&$I$47&"'!E:E"),0),0)} -> 0 | M5: =ROUND(SUM(K5:L5),2) -> 0 | N5: {=IFERROR(_xlfn.XLOOKUP(B5,INDIRECT("'"&$M$47&"'!B:B"),INDIRECT("'"&$M$47&"'!AC:AC"),0),0)} -> 0 | O5: {=IFERROR(_xlfn.XLOOKUP(B5,INDIRECT("'"&$M$47&"'!B:B"),INDIRECT("'"&$M$47&"'!AG:AG"),0),0)} -> 0 | P5: {=IFERROR(_xlfn.XLOOKUP(B5,INDIRECT("'"&$M$47&"'!B:B"),INDIRECT("'"&$M$47&"'!AB:AB"),0),0)} -> 0 | Q5: {=IFERROR(_xlfn.XLOOKUP(B5,INDIRECT("'"&$M$47&"'!B:B"),INDIRECT("'"&$M$47&"'!AD:AD"),0),0)} -> 0 | R5: {=IFERROR(_xlfn.XLOOKUP(B5,INDIRECT("'"&$M$47&"'!B:B"),INDIRECT("'"&$M$47&"'!AE:AE"),0),0)} -> 0 | S5: {=IFERROR(_xlfn.XLOOKUP(B5,INDIRECT("'"&$M$47&"'!B:B"),INDIRECT("'"&$M$47&"'!AF:AF"),0),0)} -> 0 | T5: =SUM(N5:S5) -> 0 | U5: =ROUND(SUM(M5:S5),2) -> 0 | V5: {=IFERROR(_xlfn.XLOOKUP(B5,INDIRECT("'"&$K$47&"'!B:B"),INDIRECT("'"&$K$47&"'!Y:Y"),0),0)} -> 0 | W5: =U5+V5 -> 0 | X5: {=IFERROR(_xlfn.XLOOKUP(B5,INDIRECT("'"&$K$47&"'!B:B"),INDIRECT("'"&$K$47&"'!Z:Z"),0),0)} -> 0 | Y5: =F5+X5 -> 10000 | Z5: {=IFERROR(_xlfn.LET(_xlpm.v,_xlfn.XLOOKUP(B5,INDIRECT("'"&$K$47&"'!B:B"),INDIRECT("'"&$K$47&"'!AA:AA"),0),IF(_xlpm.v=60000,60000,_xlpm.v+5000)),0)} -> 0 | AA5: =ROUND(F5-M5,2) -> 10000 | AB5: =IF(ROUND(Y5-W5-Z5,2)>0,ROUND(Y5-W5-Z5,2),0) -> 10000 | AC5: =ROUND(IF(AB5>960000,AB5*0.45-181920,IF(AB5>660000,AB5*0.35-85920,IF(AB5>420000,AB5*0.3-52920,IF(AB5>300000,AB5*0.25-31920,IF(AB5>144000,AB5*0.2-16920,IF(AB5>36000,AB5*0.1-2520,IF(AB5>0,AB5*0.03,0))))))),2) -> 300 | AD5: {=IFERROR(_xlfn.XLOOKUP(B5,INDIRECT("'"&$K$47&"'!B:B"),INDIRECT("'"&$K$47&"'!AD:AD"),0),0)} -> 0 | AE5: =ROUND(MAX(AC5-AD5,0),2) -> 300 | AF5: =ROUND(AA5-AE5,2) -> 9700
A6: =ROW(A6)-2 -> 4 | B6: 四 | C6: {=_xlfn.XLOOKUP(B6,INDIRECT("'"&$A$1&"'!B:B"),INDIRECT("'"&$A$1&"'!D:D"),"人员不存在",0,1)} -> 44986 | D6: {=_xlfn.XLOOKUP(B6,INDIRECT("'"&$A$1&"'!B:B"),INDIRECT("'"&$A$1&"'!G:G"),"人员不存在",0,1)} -> 10000 | E6: =IFERROR(F6/D6,0) -> 1 | F6: {=_xlfn.XLOOKUP(B6,INDIRECT("'"&$A$1&"'!B:B"),INDIRECT("'"&$A$1&"'!Q:Q"),"人员不存在",0,1)} -> 10000 | G6: {=SUMIF(INDIRECT("'"&$G$47&"'!C5:C"&IFERROR(MATCH(TRUE,ISBLANK(INDIRECT("'"&$G$47&"'!C5:C500")),0)+4,500)),B6,INDIRECT("'"&$G$47&"'!K5:K"&IFERROR(MATCH(TRUE,ISBLANK(INDIRECT("'"&$G$47&"'!C5:C500")),0)+4,500)))} -> 0 | H6: {=SUMIF(INDIRECT("'"&$G$47&"'!C5:C"&IFERROR(MATCH(TRUE,ISBLANK(INDIRECT("'"&$G$47&"'!C5:C500")),0)+4,500)),B6,INDIRECT("'"&$G$47&"'!L5:L"&IFERROR(MATCH(TRUE,ISBLANK(INDIRECT("'"&$G$47&"'!C5:C500")),0)+4,500)))} -> 0 | I6: {=SUMIF(INDIRECT("'"&$G$47&"'!C5:C"&IFERROR(MATCH(TRUE,ISBLANK(INDIRECT("'"&$G$47&"'!C5:C500")),0)+4,500)),B6,INDIRECT("'"&$G$47&"'!M5:M"&IFERROR(MATCH(TRUE,ISBLANK(INDIRECT("'"&$G$47&"'!C5:C500")),0)+4,500)))} -> 0 | J6: {=SUMIF(INDIRECT("'"&$G$47&"'!C5:C"&IFERROR(MATCH(TRUE,ISBLANK(INDIRECT("'"&$G$47&"'!C5:C500")),0)+4,500)),B6,INDIRECT("'"&$G$47&"'!N5:N"&IFERROR(MATCH(TRUE,ISBLANK(INDIRECT("'"&$G$47&"'!C5:C500")),0)+4,500)))} -> 0 | K6: =SUM(G6:J6) -> 0 | L6: {=IFERROR(_xlfn.XLOOKUP(B6,INDIRECT("'"&$I$47&"'!B:B"),INDIRECT("'"&$I$47&"'!E:E"),0),0)} -> 0 | M6: =ROUND(SUM(K6:L6),2) -> 0 | N6: {=IFERROR(_xlfn.XLOOKUP(B6,INDIRECT("'"&$M$47&"'!B:B"),INDIRECT("'"&$M$47&"'!AC:AC"),0),0)} -> 0 | O6: {=IFERROR(_xlfn.XLOOKUP(B6,INDIRECT("'"&$M$47&"'!B:B"),INDIRECT("'"&$M$47&"'!AG:AG"),0),0)} -> 0 | P6: {=IFERROR(_xlfn.XLOOKUP(B6,INDIRECT("'"&$M$47&"'!B:B"),INDIRECT("'"&$M$47&"'!AB:AB"),0),0)} -> 0 | Q6: {=IFERROR(_xlfn.XLOOKUP(B6,INDIRECT("'"&$M$47&"'!B:B"),INDIRECT("'"&$M$47&"'!AD:AD"),0),0)} -> 0 | R6: {=IFERROR(_xlfn.XLOOKUP(B6,INDIRECT("'"&$M$47&"'!B:B"),INDIRECT("'"&$M$47&"'!AE:AE"),0),0)} -> 0 | S6: {=IFERROR(_xlfn.XLOOKUP(B6,INDIRECT("'"&$M$47&"'!B:B"),INDIRECT("'"&$M$47&"'!AF:AF"),0),0)} -> 0 | T6: =SUM(N6:S6) -> 0 | U6: =ROUND(SUM(M6:S6),2) -> 0 | V6: {=IFERROR(_xlfn.XLOOKUP(B6,INDIRECT("'"&$K$47&"'!B:B"),INDIRECT("'"&$K$47&"'!Y:Y"),0),0)} -> 0 | W6: =U6+V6 -> 0 | X6: {=IFERROR(_xlfn.XLOOKUP(B6,INDIRECT("'"&$K$47&"'!B:B"),INDIRECT("'"&$K$47&"'!Z:Z"),0),0)} -> 0 | Y6: =F6+X6 -> 10000 | Z6: {=IFERROR(_xlfn.LET(_xlpm.v,_xlfn.XLOOKUP(B6,INDIRECT("'"&$K$47&"'!B:B"),INDIRECT("'"&$K$47&"'!AA:AA"),0),IF(_xlpm.v=60000,60000,_xlpm.v+5000)),0)} -> 0 | AA6: =ROUND(F6-M6,2) -> 10000 | AB6: =IF(ROUND(Y6-W6-Z6,2)>0,ROUND(Y6-W6-Z6,2),0) -> 10000 | AC6: =ROUND(IF(AB6>960000,AB6*0.45-181920,IF(AB6>660000,AB6*0.35-85920,IF(AB6>420000,AB6*0.3-52920,IF(AB6>300000,AB6*0.25-31920,IF(AB6>144000,AB6*0.2-16920,IF(AB6>36000,AB6*0.1-2520,IF(AB6>0,AB6*0.03,0))))))),2) -> 300 | AD6: {=IFERROR(_xlfn.XLOOKUP(B6,INDIRECT("'"&$K$47&"'!B:B"),INDIRECT("'"&$K$47&"'!AD:AD"),0),0)} -> 0 | AE6: =ROUND(MAX(AC6-AD6,0),2) -> 300 | AF6: =ROUND(AA6-AE6,2) -> 9700
A7: =ROW(A7)-2 -> 5 | B7: 五 | C7: {=_xlfn.XLOOKUP(B7,INDIRECT("'"&$A$1&"'!B:B"),INDIRECT("'"&$A$1&"'!D:D"),"人员不存在",0,1)} -> 45231 | D7: {=_xlfn.XLOOKUP(B7,INDIRECT("'"&$A$1&"'!B:B"),INDIRECT("'"&$A$1&"'!G:G"),"人员不存在",0,1)} -> 10000 | E7: =IFERROR(F7/D7,0) -> 1 | F7: {=_xlfn.XLOOKUP(B7,INDIRECT("'"&$A$1&"'!B:B"),INDIRECT("'"&$A$1&"'!Q:Q"),"人员不存在",0,1)} -> 10000 | G7: {=SUMIF(INDIRECT("'"&$G$47&"'!C5:C"&IFERROR(MATCH(TRUE,ISBLANK(INDIRECT("'"&$G$47&"'!C5:C500")),0)+4,500)),B7,INDIRECT("'"&$G$47&"'!K5:K"&IFERROR(MATCH(TRUE,ISBLANK(INDIRECT("'"&$G$47&"'!C5:C500")),0)+4,500)))} -> 0 | H7: {=SUMIF(INDIRECT("'"&$G$47&"'!C5:C"&IFERROR(MATCH(TRUE,ISBLANK(INDIRECT("'"&$G$47&"'!C5:C500")),0)+4,500)),B7,INDIRECT("'"&$G$47&"'!L5:L"&IFERROR(MATCH(TRUE,ISBLANK(INDIRECT("'"&$G$47&"'!C5:C500")),0)+4,500)))} -> 0 | I7: {=SUMIF(INDIRECT("'"&$G$47&"'!C5:C"&IFERROR(MATCH(TRUE,ISBLANK(INDIRECT("'"&$G$47&"'!C5:C500")),0)+4,500)),B7,INDIRECT("'"&$G$47&"'!M5:M"&IFERROR(MATCH(TRUE,ISBLANK(INDIRECT("'"&$G$47&"'!C5:C500")),0)+4,500)))} -> 0 | J7: {=SUMIF(INDIRECT("'"&$G$47&"'!C5:C"&IFERROR(MATCH(TRUE,ISBLANK(INDIRECT("'"&$G$47&"'!C5:C500")),0)+4,500)),B7,INDIRECT("'"&$G$47&"'!N5:N"&IFERROR(MATCH(TRUE,ISBLANK(INDIRECT("'"&$G$47&"'!C5:C500")),0)+4,500)))} -> 0 | K7: =SUM(G7:J7) -> 0 | L7: {=IFERROR(_xlfn.XLOOKUP(B7,INDIRECT("'"&$I$47&"'!B:B"),INDIRECT("'"&$I$47&"'!E:E"),0),0)} -> 0 | M7: =ROUND(SUM(K7:L7),2) -> 0 | N7: {=IFERROR(_xlfn.XLOOKUP(B7,INDIRECT("'"&$M$47&"'!B:B"),INDIRECT("'"&$M$47&"'!AC:AC"),0),0)} -> 0 | O7: {=IFERROR(_xlfn.XLOOKUP(B7,INDIRECT("'"&$M$47&"'!B:B"),INDIRECT("'"&$M$47&"'!AG:AG"),0),0)} -> 0 | P7: {=IFERROR(_xlfn.XLOOKUP(B7,INDIRECT("'"&$M$47&"'!B:B"),INDIRECT("'"&$M$47&"'!AB:AB"),0),0)} -> 0 | Q7: {=IFERROR(_xlfn.XLOOKUP(B7,INDIRECT("'"&$M$47&"'!B:B"),INDIRECT("'"&$M$47&"'!AD:AD"),0),0)} -> 0 | R7: {=IFERROR(_xlfn.XLOOKUP(B7,INDIRECT("'"&$M$47&"'!B:B"),INDIRECT("'"&$M$47&"'!AE:AE"),0),0)} -> 0 | S7: {=IFERROR(_xlfn.XLOOKUP(B7,INDIRECT("'"&$M$47&"'!B:B"),INDIRECT("'"&$M$47&"'!AF:AF"),0),0)} -> 0 | T7: =SUM(N7:S7) -> 0 | U7: =ROUND(SUM(M7:S7),2) -> 0 | V7: {=IFERROR(_xlfn.XLOOKUP(B7,INDIRECT("'"&$K$47&"'!B:B"),INDIRECT("'"&$K$47&"'!Y:Y"),0),0)} -> 0 | W7: =U7+V7 -> 0 | X7: {=IFERROR(_xlfn.XLOOKUP(B7,INDIRECT("'"&$K$47&"'!B:B"),INDIRECT("'"&$K$47&"'!Z:Z"),0),0)} -> 0 | Y7: =F7+X7 -> 10000 | Z7: {=IFERROR(_xlfn.LET(_xlpm.v,_xlfn.XLOOKUP(B7,INDIRECT("'"&$K$47&"'!B:B"),INDIRECT("'"&$K$47&"'!AA:AA"),0),IF(_xlpm.v=60000,60000,_xlpm.v+5000)),0)} -> 0 | AA7: =ROUND(F7-M7,2) -> 10000 | AB7: =IF(ROUND(Y7-W7-Z7,2)>0,ROUND(Y7-W7-Z7,2),0) -> 10000 | AC7: =ROUND(IF(AB7>960000,AB7*0.45-181920,IF(AB7>660000,AB7*0.35-85920,IF(AB7>420000,AB7*0.3-52920,IF(AB7>300000,AB7*0.25-31920,IF(AB7>144000,AB7*0.2-16920,IF(AB7>36000,AB7*0.1-2520,IF(AB7>0,AB7*0.03,0))))))),2) -> 300 | AD7: {=IFERROR(_xlfn.XLOOKUP(B7,INDIRECT("'"&$K$47&"'!B:B"),INDIRECT("'"&$K$47&"'!AD:AD"),0),0)} -> 0 | AE7: =ROUND(MAX(AC7-AD7,0),2) -> 300 | AF7: =ROUND(AA7-AE7,2) -> 9700
A8: =ROW(A8)-2 -> 6 | B8: 六 | C8: {=_xlfn.XLOOKUP(B8,INDIRECT("'"&$A$1&"'!B:B"),INDIRECT("'"&$A$1&"'!D:D"),"人员不存在",0,1)} -> 45658 | D8: {=_xlfn.XLOOKUP(B8,INDIRECT("'"&$A$1&"'!B:B"),INDIRECT("'"&$A$1&"'!G:G"),"人员不存在",0,1)} -> 10000 | E8: =IFERROR(F8/D8,0) -> 1 | F8: {=_xlfn.XLOOKUP(B8,INDIRECT("'"&$A$1&"'!B:B"),INDIRECT("'"&$A$1&"'!Q:Q"),"人员不存在",0,1)} -> 10000 | G8: {=SUMIF(INDIRECT("'"&$G$47&"'!C5:C"&IFERROR(MATCH(TRUE,ISBLANK(INDIRECT("'"&$G$47&"'!C5:C500")),0)+4,500)),B8,INDIRECT("'"&$G$47&"'!K5:K"&IFERROR(MATCH(TRUE,ISBLANK(INDIRECT("'"&$G$47&"'!C5:C500")),0)+4,500)))} -> 0 | H8: {=SUMIF(INDIRECT("'"&$G$47&"'!C5:C"&IFERROR(MATCH(TRUE,ISBLANK(INDIRECT("'"&$G$47&"'!C5:C500")),0)+4,500)),B8,INDIRECT("'"&$G$47&"'!L5:L"&IFERROR(MATCH(TRUE,ISBLANK(INDIRECT("'"&$G$47&"'!C5:C500")),0)+4,500)))} -> 0 | I8: {=SUMIF(INDIRECT("'"&$G$47&"'!C5:C"&IFERROR(MATCH(TRUE,ISBLANK(INDIRECT("'"&$G$47&"'!C5:C500")),0)+4,500)),B8,INDIRECT("'"&$G$47&"'!M5:M"&IFERROR(MATCH(TRUE,ISBLANK(INDIRECT("'"&$G$47&"'!C5:C500")),0)+4,500)))} -> 0 | J8: {=SUMIF(INDIRECT("'"&$G$47&"'!C5:C"&IFERROR(MATCH(TRUE,ISBLANK(INDIRECT("'"&$G$47&"'!C5:C500")),0)+4,500)),B8,INDIRECT("'"&$G$47&"'!N5:N"&IFERROR(MATCH(TRUE,ISBLANK(INDIRECT("'"&$G$47&"'!C5:C500")),0)+4,500)))} -> 0 | K8: =SUM(G8:J8) -> 0 | L8: {=IFERROR(_xlfn.XLOOKUP(B8,INDIRECT("'"&$I$47&"'!B:B"),INDIRECT("'"&$I$47&"'!E:E"),0),0)} -> 0 | M8: =ROUND(SUM(K8:L8),2) -> 0 | N8: {=IFERROR(_xlfn.XLOOKUP(B8,INDIRECT("'"&$M$47&"'!B:B"),INDIRECT("'"&$M$47&"'!AC:AC"),0),0)} -> 0 | O8: {=IFERROR(_xlfn.XLOOKUP(B8,INDIRECT("'"&$M$47&"'!B:B"),INDIRECT("'"&$M$47&"'!AG:AG"),0),0)} -> 0 | P8: {=IFERROR(_xlfn.XLOOKUP(B8,INDIRECT("'"&$M$47&"'!B:B"),INDIRECT("'"&$M$47&"'!AB:AB"),0),0)} -> 0 | Q8: {=IFERROR(_xlfn.XLOOKUP(B8,INDIRECT("'"&$M$47&"'!B:B"),INDIRECT("'"&$M$47&"'!AD:AD"),0),0)} -> 0 | R8: {=IFERROR(_xlfn.XLOOKUP(B8,INDIRECT("'"&$M$47&"'!B:B"),INDIRECT("'"&$M$47&"'!AE:AE"),0),0)} -> 0 | S8: {=IFERROR(_xlfn.XLOOKUP(B8,INDIRECT("'"&$M$47&"'!B:B"),INDIRECT("'"&$M$47&"'!AF:AF"),0),0)} -> 0 | T8: =SUM(N8:S8) -> 0 | U8: =ROUND(SUM(M8:S8),2) -> 0 | V8: {=IFERROR(_xlfn.XLOOKUP(B8,INDIRECT("'"&$K$47&"'!B:B"),INDIRECT("'"&$K$47&"'!Y:Y"),0),0)} -> 0 | W8: =U8+V8 -> 0 | X8: {=IFERROR(_xlfn.XLOOKUP(B8,INDIRECT("'"&$K$47&"'!B:B"),INDIRECT("'"&$K$47&"'!Z:Z"),0),0)} -> 0 | Y8: =F8+X8 -> 10000 | Z8: {=IFERROR(_xlfn.LET(_xlpm.v,_xlfn.XLOOKUP(B8,INDIRECT("'"&$K$47&"'!B:B"),INDIRECT("'"&$K$47&"'!AA:AA"),0),IF(_xlpm.v=60000,60000,_xlpm.v+5000)),0)} -> 0 | AA8: =ROUND(F8-M8,2) -> 10000 | AB8: =IF(ROUND(Y8-W8-Z8,2)>0,ROUND(Y8-W8-Z8,2),0) -> 10000 | AC8: =ROUND(IF(AB8>960000,AB8*0.45-181920,IF(AB8>660000,AB8*0.35-85920,IF(AB8>420000,AB8*0.3-52920,IF(AB8>300000,AB8*0.25-31920,IF(AB8>144000,AB8*0.2-16920,IF(AB8>36000,AB8*0.1-2520,IF(AB8>0,AB8*0.03,0))))))),2) -> 300 | AD8: {=IFERROR(_xlfn.XLOOKUP(B8,INDIRECT("'"&$K$47&"'!B:B"),INDIRECT("'"&$K$47&"'!AD:AD"),0),0)} -> 0 | AE8: =ROUND(MAX(AC8-AD8,0),2) -> 300 | AF8: =ROUND(AA8-AE8,2) -> 9700
A9: =ROW(A9)-2 -> 7 | B9: 七 | C9: {=_xlfn.XLOOKUP(B9,INDIRECT("'"&$A$1&"'!B:B"),INDIRECT("'"&$A$1&"'!D:D"),"人员不存在",0,1)} -> 45658 | D9: {=_xlfn.XLOOKUP(B9,INDIRECT("'"&$A$1&"'!B:B"),INDIRECT("'"&$A$1&"'!G:G"),"人员不存在",0,1)} -> 10000 | E9: =IFERROR(F9/D9,0) -> 1 | F9: {=_xlfn.XLOOKUP(B9,INDIRECT("'"&$A$1&"'!B:B"),INDIRECT("'"&$A$1&"'!Q:Q"),"人员不存在",0,1)} -> 10000 | G9: {=SUMIF(INDIRECT("'"&$G$47&"'!C5:C"&IFERROR(MATCH(TRUE,ISBLANK(INDIRECT("'"&$G$47&"'!C5:C500")),0)+4,500)),B9,INDIRECT("'"&$G$47&"'!K5:K"&IFERROR(MATCH(TRUE,ISBLANK(INDIRECT("'"&$G$47&"'!C5:C500")),0)+4,500)))} -> 0 | H9: {=SUMIF(INDIRECT("'"&$G$47&"'!C5:C"&IFERROR(MATCH(TRUE,ISBLANK(INDIRECT("'"&$G$47&"'!C5:C500")),0)+4,500)),B9,INDIRECT("'"&$G$47&"'!L5:L"&IFERROR(MATCH(TRUE,ISBLANK(INDIRECT("'"&$G$47&"'!C5:C500")),0)+4,500)))} -> 0 | I9: {=SUMIF(INDIRECT("'"&$G$47&"'!C5:C"&IFERROR(MATCH(TRUE,ISBLANK(INDIRECT("'"&$G$47&"'!C5:C500")),0)+4,500)),B9,INDIRECT("'"&$G$47&"'!M5:M"&IFERROR(MATCH(TRUE,ISBLANK(INDIRECT("'"&$G$47&"'!C5:C500")),0)+4,500)))} -> 0 | J9: {=SUMIF(INDIRECT("'"&$G$47&"'!C5:C"&IFERROR(MATCH(TRUE,ISBLANK(INDIRECT("'"&$G$47&"'!C5:C500")),0)+4,500)),B9,INDIRECT("'"&$G$47&"'!N5:N"&IFERROR(MATCH(TRUE,ISBLANK(INDIRECT("'"&$G$47&"'!C5:C500")),0)+4,500)))} -> 0 | K9: =SUM(G9:J9) -> 0 | L9: {=IFERROR(_xlfn.XLOOKUP(B9,INDIRECT("'"&$I$47&"'!B:B"),INDIRECT("'"&$I$47&"'!E:E"),0),0)} -> 0 | M9: =ROUND(SUM(K9:L9),2) -> 0 | N9: {=IFERROR(_xlfn.XLOOKUP(B9,INDIRECT("'"&$M$47&"'!B:B"),INDIRECT("'"&$M$47&"'!AC:AC"),0),0)} -> 0 | O9: {=IFERROR(_xlfn.XLOOKUP(B9,INDIRECT("'"&$M$47&"'!B:B"),INDIRECT("'"&$M$47&"'!AG:AG"),0),0)} -> 0 | P9: {=IFERROR(_xlfn.XLOOKUP(B9,INDIRECT("'"&$M$47&"'!B:B"),INDIRECT("'"&$M$47&"'!AB:AB"),0),0)} -> 0 | Q9: {=IFERROR(_xlfn.XLOOKUP(B9,INDIRECT("'"&$M$47&"'!B:B"),INDIRECT("'"&$M$47&"'!AD:AD"),0),0)} -> 0 | R9: {=IFERROR(_xlfn.XLOOKUP(B9,INDIRECT("'"&$M$47&"'!B:B"),INDIRECT("'"&$M$47&"'!AE:AE"),0),0)} -> 0 | S9: {=IFERROR(_xlfn.XLOOKUP(B9,INDIRECT("'"&$M$47&"'!B:B"),INDIRECT("'"&$M$47&"'!AF:AF"),0),0)} -> 0 | T9: =SUM(N9:S9) -> 0 | U9: =ROUND(SUM(M9:S9),2) -> 0 | V9: {=IFERROR(_xlfn.XLOOKUP(B9,INDIRECT("'"&$K$47&"'!B:B"),INDIRECT("'"&$K$47&"'!Y:Y"),0),0)} -> 0 | W9: =U9+V9 -> 0 | X9: {=IFERROR(_xlfn.XLOOKUP(B9,INDIRECT("'"&$K$47&"'!B:B"),INDIRECT("'"&$K$47&"'!Z:Z"),0),0)} -> 0 | Y9: =F9+X9 -> 10000 | Z9: {=IFERROR(_xlfn.LET(_xlpm.v,_xlfn.XLOOKUP(B9,INDIRECT("'"&$K$47&"'!B:B"),INDIRECT("'"&$K$47&"'!AA:AA"),0),IF(_xlpm.v=60000,60000,_xlpm.v+5000)),0)} -> 0 | AA9: =ROUND(F9-M9,2) -> 10000 | AB9: =IF(ROUND(Y9-W9-Z9,2)>0,ROUND(Y9-W9-Z9,2),0) -> 10000 | AC9: =ROUND(IF(AB9>960000,AB9*0.45-181920,IF(AB9>660000,AB9*0.35-85920,IF(AB9>420000,AB9*0.3-52920,IF(AB9>300000,AB9*0.25-31920,IF(AB9>144000,AB9*0.2-16920,IF(AB9>36000,AB9*0.1-2520,IF(AB9>0,AB9*0.03,0))))))),2) -> 300 | AD9: {=IFERROR(_xlfn.XLOOKUP(B9,INDIRECT("'"&$K$47&"'!B:B"),INDIRECT("'"&$K$47&"'!AD:AD"),0),0)} -> 0 | AE9: =ROUND(MAX(AC9-AD9,0),2) -> 300 | AF9: =ROUND(AA9-AE9,2) -> 9700
A10: =ROW(A10)-2 -> 8 | B10: 八 | C10: {=_xlfn.XLOOKUP(B10,INDIRECT("'"&$A$1&"'!B:B"),INDIRECT("'"&$A$1&"'!D:D"),"人员不存在",0,1)} -> 45809 | D10: {=_xlfn.XLOOKUP(B10,INDIRECT("'"&$A$1&"'!B:B"),INDIRECT("'"&$A$1&"'!G:G"),"人员不存在",0,1)} -> 10000 | E10: =IFERROR(F10/D10,0) -> 1 | F10: {=_xlfn.XLOOKUP(B10,INDIRECT("'"&$A$1&"'!B:B"),INDIRECT("'"&$A$1&"'!Q:Q"),"人员不存在",0,1)} -> 10000 | G10: {=SUMIF(INDIRECT("'"&$G$47&"'!C5:C"&IFERROR(MATCH(TRUE,ISBLANK(INDIRECT("'"&$G$47&"'!C5:C500")),0)+4,500)),B10,INDIRECT("'"&$G$47&"'!K5:K"&IFERROR(MATCH(TRUE,ISBLANK(INDIRECT("'"&$G$47&"'!C5:C500")),0)+4,500)))} -> 0 | H10: {=SUMIF(INDIRECT("'"&$G$47&"'!C5:C"&IFERROR(MATCH(TRUE,ISBLANK(INDIRECT("'"&$G$47&"'!C5:C500")),0)+4,500)),B10,INDIRECT("'"&$G$47&"'!L5:L"&IFERROR(MATCH(TRUE,ISBLANK(INDIRECT("'"&$G$47&"'!C5:C500")),0)+4,500)))} -> 0 | I10: {=SUMIF(INDIRECT("'"&$G$47&"'!C5:C"&IFERROR(MATCH(TRUE,ISBLANK(INDIRECT("'"&$G$47&"'!C5:C500")),0)+4,500)),B10,INDIRECT("'"&$G$47&"'!M5:M"&IFERROR(MATCH(TRUE,ISBLANK(INDIRECT("'"&$G$47&"'!C5:C500")),0)+4,500)))} -> 0 | J10: {=SUMIF(INDIRECT("'"&$G$47&"'!C5:C"&IFERROR(MATCH(TRUE,ISBLANK(INDIRECT("'"&$G$47&"'!C5:C500")),0)+4,500)),B10,INDIRECT("'"&$G$47&"'!N5:N"&IFERROR(MATCH(TRUE,ISBLANK(INDIRECT("'"&$G$47&"'!C5:C500")),0)+4,500)))} -> 0 | K10: =SUM(G10:J10) -> 0 | L10: {=IFERROR(_xlfn.XLOOKUP(B10,INDIRECT("'"&$I$47&"'!B:B"),INDIRECT("'"&$I$47&"'!E:E"),0),0)} -> 0 | M10: =ROUND(SUM(K10:L10),2) -> 0 | N10: {=IFERROR(_xlfn.XLOOKUP(B10,INDIRECT("'"&$M$47&"'!B:B"),INDIRECT("'"&$M$47&"'!AC:AC"),0),0)} -> 0 | O10: {=IFERROR(_xlfn.XLOOKUP(B10,INDIRECT("'"&$M$47&"'!B:B"),INDIRECT("'"&$M$47&"'!AG:AG"),0),0)} -> 0 | P10: {=IFERROR(_xlfn.XLOOKUP(B10,INDIRECT("'"&$M$47&"'!B:B"),INDIRECT("'"&$M$47&"'!AB:AB"),0),0)} -> 0 | Q10: {=IFERROR(_xlfn.XLOOKUP(B10,INDIRECT("'"&$M$47&"'!B:B"),INDIRECT("'"&$M$47&"'!AD:AD"),0),0)} -> 0 | R10: {=IFERROR(_xlfn.XLOOKUP(B10,INDIRECT("'"&$M$47&"'!B:B"),INDIRECT("'"&$M$47&"'!AE:AE"),0),0)} -> 0 | S10: {=IFERROR(_xlfn.XLOOKUP(B10,INDIRECT("'"&$M$47&"'!B:B"),INDIRECT("'"&$M$47&"'!AF:AF"),0),0)} -> 0 | T10: =SUM(N10:S10) -> 0 | U10: =ROUND(SUM(M10:S10),2) -> 0 | V10: {=IFERROR(_xlfn.XLOOKUP(B10,INDIRECT("'"&$K$47&"'!B:B"),INDIRECT("'"&$K$47&"'!Y:Y"),0),0)} -> 0 | W10: =U10+V10 -> 0 | X10: {=IFERROR(_xlfn.XLOOKUP(B10,INDIRECT("'"&$K$47&"'!B:B"),INDIRECT("'"&$K$47&"'!Z:Z"),0),0)} -> 0 | Y10: =F10+X10 -> 10000 | Z10: {=IFERROR(_xlfn.LET(_xlpm.v,_xlfn.XLOOKUP(B10,INDIRECT("'"&$K$47&"'!B:B"),INDIRECT("'"&$K$47&"'!AA:AA"),0),IF(_xlpm.v=60000,60000,_xlpm.v+5000)),0)} -> 0 | AA10: =ROUND(F10-M10,2) -> 10000 | AB10: =IF(ROUND(Y10-W10-Z10,2)>0,ROUND(Y10-W10-Z10,2),0) -> 10000 | AC10: =ROUND(IF(AB10>960000,AB10*0.45-181920,IF(AB10>660000,AB10*0.35-85920,IF(AB10>420000,AB10*0.3-52920,IF(AB10>300000,AB10*0.25-31920,IF(AB10>144000,AB10*0.2-16920,IF(AB10>36000,AB10*0.1-2520,IF(AB10>0,AB10*0.03,0))))))),2) -> 300 | AD10: {=IFERROR(_xlfn.XLOOKUP(B10,INDIRECT("'"&$K$47&"'!B:B"),INDIRECT("'"&$K$47&"'!AD:AD"),0),0)} -> 0 | AE10: =ROUND(MAX(AC10-AD10,0),2) -> 300 | AF10: =ROUND(AA10-AE10,2) -> 9700
